Workbook

Sheet Data Summary
A1: Bulletin Reports Summary for Apr-19
A2: Report Name | B2: Data Status
A3: Table 1: SEBI Registered Market Intermediaries/Institutions | B3: Data Available
A4: Table 2: Company-Wise Capital Raised through Public and Rights Issues (Equity) | B4: Data Available
A5: Table 3: Open Offers under SEBI Takeover Code closed | B5: Data Available
A6: Table 4: Substantial Acquisition of Shares and Takeovers | B6: Data Available
A7: Table 5: Capital Raised from the Primary Market through though Public and Rights Issues | B7: Data Available
A8: Table 6: Issues Listed on SME Platform | B8: Data Available
A9: Table 7: Industry-wise Classification of Capital Raised through Public and Rights Issues | B9: Data Available
A10: Table 8: Sector-wise and Region-wise Distribution of Capital Mobilised through Public and Rights Issues | B10: Data Available
A11: Table 9: Size-wise Classification of Capital Raised through Public and Rights Issues | B11: Data Available
A12: Table 10: Capital Raised by Listed Companies from the Primary Market through QIPs | B12: Data Available
A13: Table 11: Preferential Allotments Listed at BSE and NSE | B13: Data Available
... A76: Table 74: Macro Economic Indicators | B76: Data Available

Sheet 1
A1: Table 1: SEBI Registered Market Intermediaries/Institutions
A2: Market Intermediaries | B2: 2018-19 | C2: 2019-20$
A3: Stock Exchanges (Cash Segment) | B3: 5 | C3: 5
A4: Stock Exchanges (Equity Derivatives Segment) | B4: 3 | C4: 3
A5: Stock Exchanges (Currency Derivatives Segment) | B5: 3 | C5: 3
A6: Stock Exchanges (Commodity Derivatives Segment) | B6: 5 | C6: 5
A7: Brokers (Cash Segment) | B7: 2315 | C7: 2282
A8: Brokers (Equity Derivatives Segment) | B8: 2435 | C8: 2435
A9: Brokers (Currency Derivatives Segment) | B9: 2110 | C9: 2092
A10: Brokers (Debt Segment) | B10: 173 | C10: 173
A11: Brokers (Commodity Derivatives Segment) | B11: 1708 | C11: 1703
A12: Corporate Brokers(Cash Segment) | B12: 2004 | C12: 1975
A13: Foreign Portfolio Investors (FPIs) | B13: 9390 | C13: 9385
A14: Custodians | B14: 20 | C14: 20
... A37: STP Service Providers | B37: 2 | C37: 2
A38: Notes:
A39: $ indicates as on April 30,2019
A40: Source: SEBI, NSDL.

Sheet 2
A1: Table 2: Company-Wise Capital Raised through Public and Rights Issues (Equity)
A2: Sl.No. | B2: Name of the Issuer/Company | C2: Date of Opening | D2: Type of Issue | E2: Type of Instrument | F2: No. of Shares Issued | G2: Face Value (`) | H2: Premium Value (`) | I2: Issue Price (`) | J2: Size of Issue (` Crore)
A3: 1 | B3: Vodafone Idea Limited | C3: 43579 | D3: Rights | E3: Equity | F3: 19999830911 | G3: 10 | H3: 2.5 | I3: 12.5 | J3: 24999.788
A4: 2 | B4: Polycab India Limited | C4: 43564 | D4: IPO | E4: Equity | F4: 25022067 | G4: 10 | H4: 528 | I4: 538 | J4: 1345.26
A5: 3 | B5: Metropolis Healthcare Limited | C5: 43560 | D5: IPO | E5: Equity | F5: 13685095 | G5: 2 | H5: 878 | I5: 880 | J5: 1204.29
A6: 4 | B6: Rail Vikas Nigam Limited | C6: 43558 | D6: IPO | E6: Equity | F6: 253457280 | G6: 10 | H6: 9 | I6: 19 | J6: 477.11
A7: 5 | B7: Jinaam's Dress Limited | C7: 43570 | D7: SME IPO | E7: Equity | F7: 7200000 | G7: 10 | H7: 49 | I7: 59 | J7: 42.48
A8: 6 | B8: Bharat Gears Ltd | C8: 43585 | D8: Rights | E8: Equity | F8: 1163262 | G8: 10 | H8: 95 | I8: 105 | J8: 12.21
A9: 7 | B9: KHFM Hospitality and Facility Management Serv Ltd | C9: 43551 | D9: SME IPO | E9: Equity | F9: 2949000 | G9: 10 | H9: 26 | I9: 36 | J9: 10.62
A10: 8 | B10: G.K.P. Printing & Packaging Limited | C10: 43581 | D10: SME IPO | E10: Equity | F10: 2056000 | G10: 10 | H10: 22 | I10: 32 | J10: 6.58
A11: 9 | B11: V R Films & Studios Limited | C11: 43573 | D11: SME IPO | E11: Equity | F11: 372000 | G11: 10 | H11: 51 | I11: 61 | J11: 2.27
A12: 10 | B12: Neogen Chemicals Limited | C12: 43581 | D12: IPO | E12: Equity | F12: 6155813 | G12: 10 | H12: 205 | I12: 215 | J12: 132.35
A13: Note: All the issues are compiled from the Prospectus of Issuer Companies filed with SEBI.
A14: Source: SEBI.

Sheet 3
A1: Table 3: Open Offers under SEBI Takeover Code closed during Mar-19
A2: Sl.No | B2: Target Company | C2: Acquirer | D2: Offer Opening Date | E2: Offer Closing Date | F2: Offer Size | H2: Offer Price (`) per share | I2: Offer Size (` Crore)
F3: No. of Shares | G3: Percent of Equity Capital
A4: 1 | B4: HATHWAY BHAWANI CABLETEL AND DATACOM LIMITED | C4: JIO CONTENT DISTRIBUTION HOLDINGS PVT LTD, JIO INTERNET DISTRIBUTION HOLDINGS PVT. LTD., JIO CABLE A | D4: 43546 | E4: 43559 | F4: 2106000 | G4: 26 | H4: 2.46 | I4: 0.52
A5: Source: SEBI.

Sheet 4
A1: Table 4: Substantial Acquisition of Shares and Takeovers
A2: Year / Month | B2: Open Offers
B3: Objectives | H3: Total
B4: Change in Control of Management | D4: Consolidation of Holdings | F4: Substantial Acquisition | H4: No. of Offers | I4: Amount (` crore)
B5: No. of Offers | C5: Amount (` crore) | D5: No. of Offers | E5: Amount (` crore) | F5: No. of Offers | G5: Amount (` crore)
A6: 2018-19 | B6: 63 | C6: 23015.99 | D6: 4 | E6: 4636.33 | F6: 4 | G6: 941.23 | H6: 71 | I6: 28593.55
A7: 2019-20$ | B7: 3 | C7: 24.55 | D7: 1 | E7: 31.82 | F7: 0 | G7: 0 | H7: 4 | I7: 56.37
A8: Apr-19 | B8: 3 | C8: 24.55 | D8: 1 | E8: 31.82 | F8: 0 | G8: 0 | H8: 4 | I8: 56.37
A9: $ indicates as on April 30, 2019
A10: Source: SEBI.

Sheet 5
A1: Table 5: Capital Raised from the Primary Market through though Public and Rights Issues
A2: Year / Month | B2: Total | D2: Category-Wise | H2: Issue-Type | L2: Instrument-Wise
D3: Public | F3: Rights | H3: Listed | J3: IPOs | L3: Equities | P3: CCPS/FCDs* | R3: Debt
L4: At Par | N4: At Premium
B5: No. of issues | C5: Amount (` crore) | D5: No. of issues | E5: Amount (` crore) | F5: No. of issues | G5: Amount (` crore) | H5: No. of issues | I5: Amount (` crore) | J5: No. of issues | K5: Amount (` crore) | L5: No. of issues | M5: Amount (` crore) | N5: No. of issues | O5: Amount (` crore) | P5: No. of issues | Q5: Amount (` crore) | R5: No. of issues | S5: Amount (` crore)
A6: 2018-19 | B6: 158 | C6: 54914.58 | D6: 148 | E6: 52765.93 | F6: 10 | G6: 2148.65 | H6: 35 | I6: 38828.04 | J6: 123 | K6: 16086.54 | L6: 6 | M6: 512.57 | N6: 127 | O6: 17722.62 | P6: 0 | Q6: 0 | R6: 25 | S6: 36679.39
A7: 2019-20$ | B7: 12 | C7: 29349.68 | D7: 10 | E7: 4337.68 | F7: 2 | G7: 25012 | H7: 4 | I7: 26128.72 | J7: 8 | K7: 3220.96 | L7: 0 | M7: 0 | N7: 10 | O7: 28232.96 | P7: 0 | Q7: 0 | R7: 2 | S7: 1116.72
A8: Apr-19 | B8: 12 | C8: 29349.68 | D8: 10 | E8: 4337.68 | F8: 2 | G8: 25012 | H8: 4 | I8: 26128.72 | J8: 8 | K8: 3220.96 | L8: 0 | M8: 0 | N8: 10 | O8: 28232.96 | P8: 0 | Q8: 0 | R8: 2 | S8: 1116.72
A9: Notes: 1. The total provides category-wise total of any of the three sub-categories viz. public plus rights or issuer-type(listed plus IPOs) or instrument-wise(equities plus CCPS/FCDs plus debt). 2. Amount for public debt issue for last two months is provisional and may get updated 3. All the Issues are compiled from the Prospectus. of Issuer Companies filed with SEBI. 4. * CCPS: Compulsory Convertible Preference Shares, FCDs: Fully Convertible Debentures.
A10: 5. Equity public issues also includes issues listed on SME platform.
A11: 6. Since April 2018, both the equity and debt issues are categorised based on their respective closing dates. Prior to April 2018, the equity issues were classified based on opening date of the issue, while debt issues were classfied based on closing date of the issue.
A12: $ indicates as on April 30,2019
A13: Source: SEBI.

Sheet 6
A1: Table 6: Issues Listed on SME Platform
A2: Year/ Month | B2: Total
B3: No. of issue | C3: Amount (`crore)
A4: 2018-19 | B4: 110 | C4: 1844
A5: 2019-20$ | B5: 3 | C5: 51.3292
A6: Apr-19 | B6: 3 | C6: 51.3292
A7: $ indicates as on April 30,2019
A8: Source: SEBI

Sheet 7
A1: Table 7: Industry-wise Classification of Capital Raised through Public and Rights Issues
A2: Industry | B2: 2019-20$ | D2: Apr-19
B3: No. of issues | C3: Amount (`crore) | D3: No. of issues | E3: Amount (` crore)
A4: Airlines | B4: 0 | C4: 0 | D4: 0 | E4: 0
A5: Automobiles | B5: 1 | C5: 12.21 | D5: 1 | E5: 12.21
A6: Banks/FIs | B6: 0 | C6: 0 | D6: 0 | E6: 0
A7: Cement/ Constructions | B7: 0 | C7: 0 | D7: 0 | E7: 0
A8: Chemical | B8: 1 | C8: 132.35 | D8: 1 | E8: 132.35
A9: Consumer Services | B9: 0 | C9: 0 | D9: 0 | E9: 0
A10: Electronic Equipments/ Products | B10: 1 | C10: 1345.26 | D10: 1 | E10: 1345.26
A11: Engineering | B11: 1 | C11: 477.11 | D11: 1 | E11: 477.11
A12: Entertainment | B12: 1 | C12: 2.27 | D12: 1 | E12: 2.27
A13: Finance | B13: 2 | C13: 1116.72 | D13: 2 | E13: 1116.72
A14: Food processing | B14: 0 | C14: 0 | D14: 0 | E14: 0
A15: Healthcare | B15: 1 | C15: 1204.29 | D15: 1 | E15: 1204.29
... A27: Total | B27: 12 | C27: 29349.68 | D27: 12 | E27: 29349.68
A28: $ indicates as on April 30,2019
A29: Source: SEBI.

Sheet 8
A1: Table 8: Sector-wise and Region-wise Distribution of Capital Mobilised through Public and Rights Issues
A2: Year / Month | B2: Total | D2: Sector-wise | H2: Region-wise
D3: Private | F3: Public | H3: Northern | J3: Eastern | L3: Western | N3: Southern | P3: Central | R3: Foreign
B4: No. of Issue | C4: Amount (`Crores) | D4: No. of Issue | E4: Amount (` Crores) | F4: No. of Issue | G4: Amount (` Crores) | H4: No. of Issue | I4: Amount (` Crores) | J4: No. of Issue | K4: Amount (` Crores) | L4: No. of Issue | M4: Amount (` Crores) | N4: No. of Issue | O4: Amount (` Crores) | P4: No. of Issue | Q4: Amount (` Crores) | R4: No. of Issue | S4: Amount (` Crores)
A5: 2018-19 | B5: 158 | C5: 54916.58 | D5: 154 | E5: 53434.74 | F5: 4 | G5: 1481.84 | H5: 24 | I5: 3338.36 | J5: 8 | K5: 1155.2095 | L5: 85 | M5: 35717.24 | N5: 20 | O5: 12175.42 | P5: 4 | Q5: 115.7 | R5: 0 | S5: 0
A6: 2019-20$ | B6: 12 | C6: 29349.68 | D6: 11 | E6: 28872.57 | F6: 1 | G6: 477.11 | H6: 3 | I6: 1834.58 | J6: 0 | K6: 0 | L6: 8 | M6: 27398.38 | N6: 1 | O6: 116.72 | P6: 0 | Q6: 0 | R6: 0 | S6: 0
A7: Apr-19 | B7: 12 | C7: 29349.68 | D7: 11 | E7: 28872.57 | F7: 1 | G7: 477.11 | H7: 3 | I7: 1834.58 | J7: 0 | K7: 0 | L7: 8 | M7: 27398.38 | N7: 1 | O7: 116.72 | P7: 0 | Q7: 0 | R7: 0 | S7: 0
A8: $ indicates as on April 30,2019
A9: Source: SEBI.

Sheet 9
A1: Table 9: Size-wise Classification of Capital Raised through Public and Rights Issues
A2: Year / Month | B2: Total | D2: < 5 crore | F2: ≥ 5crore - < 10crore | H2: ≥ 10 crore - < 50 crore | J2: ≥ 50 crore - < 100 crore | L2: ≥ 100 crore
B3: No. of issue | C3: Amount (` crore) | D3: No. of issue | E3: Amount (` crore) | F3: No. of issue | G3: Amount (` crore) | H3: No. of issue | I3: Amount (` crore) | J3: No. of issue | K3: Amount (` crore) | L3: No. of issue | M3: Amount (` crore)
A4: 2018-19 | B4: 158 | C4: 54916.6 | D4: 20 | E4: 68.41 | F4: 29 | G4: 212.75 | H4: 61 | I4: 1355.19 | J4: 6 | K4: 437.52 | L4: 42 | M4: 52842.73
A5: 2019-20$ | B5: 12 | C5: 29349.68 | D5: 1 | E5: 2.27 | F5: 1 | G5: 6.58 | H5: 3 | I5: 65.31 | J5: 0 | K5: 0 | L5: 7 | M5: 29275.52
A6: Apr-19 | B6: 12 | C6: 29349.68 | D6: 1 | E6: 2.27 | F6: 1 | G6: 6.58 | H6: 3 | I6: 65.31 | J6: 0 | K6: 0 | L6: 7 | M6: 29275.52
A7: $ indicates as on April 30,2019
A8: Source: SEBI.

Sheet 10
A1: Table 10: Capital Raised by Listed Companies from the Primary Market through QIPs
A2: Year / Month | B2: Only BSE | D2: Only NSE | F2: Only MSEI | H2: Both NSE and BSE | J2: Total
B3: No. of issues | C3: Amount (` Crores) | D3: No. of issues | E3: Amount (` Crores) | F3: No. of issues | G3: Amount (` Crores) | H3: No. of issues | I3: Amount (` Crores) | J3: No. of issues | K3: Amount (` Crores)
A4: 2018-19 | B4: 1 | C4: 113.25139 | D4: 0 | E4: 0 | F4: 0 | G4: 0 | H4: 13 | I4: 8565.0668 | J4: 14 | K4: 8678.3182
A5: 2019-20$ | B5: 0 | C5: 0 | D5: 0 | E5: 0 | F5: 0 | G5: 0 | H5: 1 | I5: 3172.82 | J5: 1 | K5: 3172.82
A6: Apr-19 | B6: 0 | C6: 0 | D6: 0 | E6: 0 | F6: 0 | G6: 0 | H6: 1 | I6: 3172.82 | J6: 1 | K6: 3172.82
A7: Notes: 1. The above data includes both "no. of issues" and "Amount" raised on conversion of convertible securities issued on QIP basis. 2. 2017-18, Includes one issue of Institutional Placement Programme (Issue Size of Rs. 873.92 crore).
A8: $ indicates as on April 30,2019
A9: Source: BSE, NSE and MSEI.

Sheet 11
A1: Table 11: Preferential Allotments Listed at BSE and NSE
A2: Year/Month | B2: Only BSE | D2: Only NSE | F2: Only MSEI | H2: Both NSE and BSE | J2: Total
B3: No. of issues | C3: Amount (` Crores) | D3: No. of issues | E3: Amount (` Crores) | F3: No. of issues | G3: Amount (`Crores) | H3: No. of issues | I3: Amount ` Crores) | J3: No. of issues | K3: Amount (`Crores)
A4: 2018-19 | B4: 208 | C4: 10824.71 | D4: 20 | E4: 8032.005 | F4: 4 | G4: 23.59 | H4: 171 | I4: 191281.42 | J4: 403 | K4: 210161.72
A5: 2019-20$ | B5: 7 | C5: 21.53 | D5: 0 | E5: 0 | F5: 0 | G5: 0 | H5: 16 | I5: 35806.25 | J5: 23 | K5: 35827.78
A6: Apr-19 | B6: 7 | C6: 21.53 | D6: 0 | E6: 0 | F6: 0 | G6: 0 | H6: 16 | I6: 35806.25 | J6: 23 | K6: 35827.78
A7: $ indicates as on April 30,2019
A8: Source: BSE, NSE and MSEI.

Sheet 12
A1: Table 12: Private Placement of Corporate Debt Reported to BSE and NSE
A2: Year/Month | B2: Only BSE | D2: Only NSE | F2: Both NSE and BSE | H2: TOTAL
B3: No. of Issues | C3: Amount (`Crores) | D3: No. of Issues | E3: Amount (` Crores) | F3: No. of Issues | G3: Amount (` Crores) | H3: No. of Issues | I3: Amount (` Crores)
A4: 2018-19 | B4: 479 | C4: 177592.59 | D4: 1703 | E4: 247190.35 | F4: 176 | G4: 185274.02 | H4: 2358 | I4: 579424.55
A5: 2019-20$ | B5: 39 | C5: 26394.183 | D5: 174 | E5: 31434.83 | F5: 11 | G5: 12235.204 | H5: 224 | I5: 70064.217
A6: Apr-19 | B6: 39 | C6: 26394.183 | D6: 174 | E6: 31434.83 | F6: 11 | G6: 12235.204 | H6: 224 | I6: 70064.217
A7: $ indicates as on April 30, 2019
A8: Source: BSE and NSE

Sheet 13
A1: Table 13: Trading in the Corporate Debt Market
A2: Year / Month | B2: BSE | D2: NSE | F2: MSEI | H2: Total
B3: No. of Trades | C3: Traded Value (` crore) | D3: No. of Trades | E3: Traded Value (` crore) | F3: No. of Trades | G3: Traded Value (` crore) | H3: No. of Trades | I3: Traded Value (` crore)
A4: 2018-19 | B4: 43157 | C4: 631252.22 | D4: 60370 | E4: 1168407.7 | F4: 0 | G4: 0 | H4: 103527 | I4: 1799659.9
A5: 2019-20$ | B5: 3944 | C5: 53755.86 | D5: 5380 | E5: 90747.82 | F5: 0 | G5: 0 | H5: 9324 | I5: 144503.68
A6: Apr-19 | B6: 3944 | C6: 53755.86 | D6: 5380 | E6: 90747.82 | F6: 0 | G6: 0 | H6: 9324 | I6: 144503.68
A7: $ indicates as on April 30, 2019
A8: Source: BSE, NSE and MSEI.

Sheet 14
A1: Table 14: Ratings Assigned for Long-term Corporate Debt Securities (Maturity ≥ 1 year)
A2: Grade | B2: Investment Grade | J2: Non-Investment Grade | L2: Total
B3: Highest Safety (AAA) | D3: High Safety (AA) | F3: Adequate Safety (A) | H3: Moderate Safety (BBB)
A4: Period | B4: No. of issue | C4: Amount (`crore) | D4: No. of issue | E4: Amount (` crore) | F4: No. of issue | G4: Amount (` crore) | H4: No. of issue | I4: Amount (` crore) | J4: No. of issue | K4: Amount (` crore) | L4: No. of issue | M4: Amount (` crore)
A5: 2018-19 | B5: 279 | C5: 2080535.8 | D5: 400 | E5: 324988.84 | F5: 349 | G5: 104665.52 | H5: 241 | I5: 20878.506 | J5: 57 | K5: 12738.1 | L5: 1326 | M5: 2543806.7
A6: 2019-20$ | B6: 8 | C6: 105452 | D6: 4 | E6: 2850 | F6: 6 | G6: 1482.5 | H6: 1 | I6: 495 | J6: 7 | K6: 3072 | L6: 26 | M6: 113351.5
A7: Apr-19 | B7: 8 | C7: 105452 | D7: 4 | E7: 2850 | F7: 6 | G7: 1482.5 | H7: 1 | I7: 495 | J7: 7 | K7: 3072 | L7: 26 | M7: 113351.5
A8: $ indicates as on April 30,2019
A9: Source: Credit Rating Agencies.

Sheet 15
A1: Table 15: Review of Accepted Ratings of Corporate Debt Securities (Maturity ≥ 1 year)
A2: Grade | B2: Upgraded | D2: Downgraded | F2: Reaffirmed | H2: Rating Watch | J2: Withdrawn/ Suspended | L2: Total
A3: Period | B3: No. of issue | C3: Amount (`crore) | D3: No. of issue | E3: Amount (`crore) | F3: No. of issue | G3: Amount (`crore) | H3: No. of issue | I3: Amount (`crore) | J3: No. of issue | K3: Amount (`crore) | L3: No. of issue | M3: Amount (`crore)
A4: 2018-19 | B4: 711 | C4: 314241.22 | D4: 892 | E4: 913562.25 | F4: 5489 | G4: 12252045 | H4: 494 | I4: 1124407.7 | J4: 1101 | K4: 475759.98 | L4: 8687 | M4: 15079016
A5: 2019-20$ | B5: 4 | C5: 21200 | D5: 148 | E5: 186753.51 | F5: 62 | G5: 71602.33 | H5: 136 | I5: 226341.18 | J5: 29 | K5: 2545 | L5: 379 | M5: 508442.02
A6: Apr-19 | B6: 4 | C6: 21200 | D6: 148 | E6: 186753.51 | F6: 62 | G6: 71602.33 | H6: 136 | I6: 226341.18 | J6: 29 | K6: 2545 | L6: 379 | M6: 508442.02
A7: $ indicates as on April 30,2019
A8: Source: Credit Rating Agencies.

Sheet 16
A1: Table 16: Distribution of Turnover on Cash Segments of Stock Exchanges (`crore)
A2: Stock Exchanges | B2: 2018-19 | C2: 2019-20$ | D2: Apr-19
A3: BSE | B3: 775590.08 | C3: 55867.81 | D3: 55867.81
A4: MSEI | B4: 30.29325 | C4: 7.4556996 | D4: 7.4556996
A5: NSE | B5: 7949004.3 | C5: 640115.39 | D5: 640115.39
A6: $ indicates as on April 30, 2019
A7: Source: BSE, NSE and MSEI.

Sheet 17
A1: Table 17: Trends in Cash Segment of BSE
A2: Year / Month | B2: No. of Companies Listed | C2: No. of Companies Permitted* | D2: No. of companies traded | E2: No. of Trading Days | F2: No. of Trades (Lakh) | G2: Traded Quantity (Lakh) | H2: Turnover (` crore) | I2: Average Daily Turnover (` crore) | J2: Average Trade Size (`) | K2: Demat Securities Traded (Lakh) | L2: Demat Turnover (` crore) | M2: Market Capitalisation (` crore) | N2: S&P BSE Sensex
N3: High | O3: Low | P3: Close
A4: 2018-19 | B4: 5262 | C4: 36 | D4: 4086 | E4: 248 | F4: 3145.25 | G4: 518103.44 | H4: 775590.08 | I4: 3127.3794 | J4: 24659.092 | K4: 518103.44 | L4: 775589.97 | M4: 15108711 | N4: 38989.65 | O4: 32972.56 | P4: 38672.91
A5: 2019-20$ | B5: 5282 | C5: 36 | D5: 3580 | E5: 19 | F5: 254.6 | G5: 76938.82 | H5: 55867.81 | I5: 2940.4111 | J5: 21943.366 | K5: 76938.82 | L5: 55867.81 | M5: 15254028 | N5: 39487.45 | O5: 38460.25 | P5: 39031.55
A6: Apr-19 | B6: 5282 | C6: 36 | D6: 3580 | E6: 19 | F6: 254.6 | G6: 76938.82 | H6: 55867.81 | I6: 2940.4111 | J6: 21943.366 | K6: 76938.82 | L6: 55867.81 | M6: 15254028 | N6: 39487.45 | O6: 38460.25 | P6: 39031.55
A7: $ indicates as on April 30,2019
A8: Source: BSE .

Sheet 18
A1: Table 18: Trends in Cash Segment of NSE
A2: Year / Month | B2: No. of Companies Listed | C2: No. of Companies Permitted* | D2: No. of companies traded | E2: No. of Trading Days | F2: No. of Trades (Lakh) | G2: Traded Quantity (Lakh) | H2: Turnover (` crore) | I2: Average Daily Turnover (` crore) | J2: Average Trade Size (`) | K2: Demat Securities Traded (Lakh) | L2: Demat Turnover (` crore) | M2: Market Capitalisation (` crore) | N2: Nifty 50 Index
N3: High | O3: Low | P3: Close
A4: 2018-19 | B4: 1931 | C4: 4 | D4: 1922 | E4: 248 | F4: 28531.564 | G4: 3749975.9 | H4: 7949004.3 | I4: 32052.437 | J4: 27860.387 | K4: 3749975.9 | L4: 7949004.3 | M4: 14934227 | N4: 11760.2 | O4: 10004.55 | P4: 11623.9
A5: 2019-20$ | B5: 1938 | C5: 4 | D5: 1856 | E5: 19 | F5: 2147.241 | G5: 308635.83 | H5: 640115.39 | I5: 33690.284 | J5: 29811.064 | K5: 308635.83 | L5: 640115.39 | M5: 15043276 | N5: 11856.15 | O5: 11549.1 | P5: 11748.15
A6: Apr-19 | B6: 1938 | C6: 4 | D6: 1856 | E6: 19 | F6: 2147.241 | G6: 308635.83 | H6: 640115.39 | I6: 33690.284 | J6: 29811.064 | K6: 308635.83 | L6: 640115.39 | M6: 15043276 | N6: 11856.15 | O6: 11549.1 | P6: 11748.15
A7: Turnover Data compiled for all markets except auction market
A8: $ indicates as on April 30,2019
A9: Source: NSE

Sheet 19
A1: Table 19: Trends in Cash Segment of MSEI
A2: Year/Month | B2: No. of Companies Listed | C2: No. of Companies Permitted # | D2: No. of Companies Traded | E2: No. of Trading Days | F2: No. of Trades (Lakh) | G2: Traded Quantity (Lakh) | H2: Turnover (₹ crore) | I2: Average Daily Turnover (₹ crore) | J2: Average Trade Size (`) | K2: Demat Securities Traded (Lakh) | L2: Demat Turnover (₹ crore) | M2: Market Capitalisation (₹ crore) | N2: SX 50 Index
N3: High | O3: Low | P3: Close
A4: 2018-19 | B4: 287 | C4: 1309 | D4: 8 | E4: 248 | F4: 0.01911 | G4: 14.16864 | H4: 30.29325 | I4: 0.1221502 | J4: 158520.41 | K4: 14.16853 | L4: 30.288544 | M4: 14751584 | N4: 22872.75 | O4: 19644.59 | P4: 22743.31
A5: 2019-20$ | B5: 286 | C5: 1308 | D5: 6 | E5: 19 | F5: 0.00227 | G5: 3.82974 | H5: 7.4556996 | I5: 0.39240524 | J5: 328444.92 | K5: 3.82974 | L5: 7.4557 | M5: 14842661 | N5: 23072 | O5: 22659.08 | P5: 23000.87
A6: Apr-19 | B6: 286 | C6: 1308 | D6: 6 | E6: 19 | F6: 0.00227 | G6: 3.82974 | H6: 7.4556996 | I6: 0.39240524 | J6: 328444.92 | K6: 3.82974 | L6: 7.4557 | M6: 14842661 | N6: 23072 | O6: 22659.08 | P6: 23000.87
A7: $ indicates as on April 30, 2019
A8: Source: MSEI

Sheet 20
A1: Table 20: City-wise Distribution of Turnover on Cash Segments of BSE and NSE
A2: (Percentage share in Turnover)
A3: S.No | B3: City | C3: BSE | E3: NSE | G3: MSEI
C4: 2018-19 | D4: Apr-19 | E4: 2018-19 | F4: Apr-19 | G4: 2018-19 | H4: Apr-19
A5: 1 | B5: Ahmedabad | C5: 2.540772 | D5: 2.1284174 | E5: 2.24 | F5: 1.9 | G5: 0 | H5: 0
A6: 2 | B6: Bengaluru | C6: 0.453121 | D6: 0.9583561 | E6: 3.84 | F6: 3 | G6: 0 | H6: 0
A7: 3 | B7: Vadodra | C7: 0.907871 | D7: 0.94489403 | E7: 0.3 | F7: 0.24 | G7: 0 | H7: 0
A8: 4 | B8: Bhubneshwar | C8: 0.019895 | D8: 0.014461141 | E8: 0 | F8: 0 | G8: 0 | H8: 0
A9: 5 | B9: Chennai | C9: 1.090857 | D9: 1.2186534 | E9: 0.86 | F9: 0.82 | G9: 0 | H9: 0
A10: 6 | B10: Ernakulum | C10: 0.104662 | D10: 0.088157028 | E10: 0.75 | F10: 0.8 | G10: 0 | H10: 0
A11: 7 | B11: Coimbatore | C11: 0.042661 | D11: 0.03940365 | E11: 0.05 | F11: 0.04 | G11: 0 | H11: 0
A12: 8 | B12: New Delhi | C12: 1.604574 | D12: 1.3625655 | E12: 6.34 | F12: 6.57 | G12: 29.35 | H12: 49.36
A13: 9 | B13: Guwahati | C13: 0.046059 | D13: 0.032742056 | E13: 0 | F13: 0 | G13: 0 | H13: 0
A14: 10 | B14: Hyderabad | C14: 0.428016 | D14: 0.79549534 | E14: 3.36 | F14: 3.17 | G14: 0.08 | H14: 0
A15: 11 | B15: Indore | C15: 0.350443 | D15: 0.35068354 | E15: 0.44 | F15: 0.32 | G15: 0 | H15: 0
A16: 12 | B16: Jaipur | C16: 0.558991 | D16: 0.5517098 | E16: 0.32 | F16: 0.3 | G16: 0.09 | H16: 0
... A25: 21 | B25: Others | C25: 30.59857 | D25: 32.283089 | E25: 10.84 | F25: 11.38 | G25: 29.82 | H25: 35.51
B26: Total | C26: 100 | D26: 100 | E26: 100.02 | F26: 100 | G26: 100 | H26: 100
A27: Notes:
A28: 1. The city-wise distribution of turnover is based on the cities uploaded in the UCC database of the Exchange for clientele trades and members registered office city for proprietary trades.
A29: Source: BSE, NSE and MSEI.

Sheet 21
A1: Table 21: Category-wise Share of Turnover in Cash Segment of BSE
A2: Year / Month | B2: Percentage Share in Turnover
B3: Proprietary | C3: FPIs | D3: Mutual Funds | E3: Banks | F3: Others
A4: 2018-19 | B4: 22.3525 | C4: 12.430833 | D4: 7.94 | E4: 0.051666667 | F4: 57.224167
A5: 2019-20$ | B5: 22.47 | C5: 7.12 | D5: 6.77 | E5: 0.04 | F5: 63.59
A6: Apr-19 | B6: 22.47 | C6: 7.12 | D6: 6.77 | E6: 0.04 | F6: 63.59
A7: $ indicates as on April 30,2019
A8: Source: BSE.

Sheet 22
A1: Table 22: Category-wise Share of Turnover in Cash Segment of NSE
A2: Year /Month | B2: Percentage Share in Turnover
B3: Proprietary | C3: FPIs | D3: Mutual Funds | E3: Banks | F3: Others
A4: 2018-19 | B4: 21.53 | C4: 15.1 | D4: 7.49 | E4: 0.22 | F4: 55.66
A5: 2019-20$ | B5: 22.66 | C5: 14.33 | D5: 6.69 | E5: 0.15 | F5: 56.17
A6: Apr-19 | B6: 22.66 | C6: 14.33 | D6: 6.69 | E6: 0.15 | F6: 56.17
A7: $ indicates as on April 30,2019
A8: Source: NSE.

Sheet 23
A1: Table 23: Category-wise Share of Turnover in Cash Segment of MSEI
A2: Year / Month | B2: Percentage Share in Turnover
B3: Proprietary | C3: FPIs | D3: Mutual Funds | E3: Banks | F3: Others
A4: 2018-19 | B4: 0 | C4: 0 | D4: 0 | E4: 0 | F4: 100
A5: 2019-20$ | B5: 0 | C5: 0 | D5: 0 | E5: 0 | F5: 100
A6: Apr-19 | B6: 0 | C6: 0 | D6: 0 | E6: 0 | F6: 100
A7: $ indicates as on April 30, 2019
A8: Source: MSEI.

Sheet 24
A1: Table 24: Component Stocks: S&P BSE Sensex during Apr-19
A2: Sl.No | B2: Name of Security | C2: Issued Capital (` crore) | D2: Free Float Market Capitalisation (` crore) | E2: Weightage (Percent) | F2: Beta | G2: R 2 | H2: Daily Volatility (Percent) | I2: Monthly Return (Percent) | J2: Impact Cost (Percent)
A3: 1 | B3: HDFC BANK | C3: 545.01 | D3: 497038.06 | E3: 12.518176 | F3: 0.71 | G3: 0.306229 | H3: 0.99 | I3: -0.043168 | J3: 0.04
A4: 2 | B4: RELIANCE | C4: 6338.75 | D4: 449532.35 | E4: 11.321719 | F4: 1.5 | G4: 0.463172 | H4: 1.72 | I4: 2.10924 | J4: 0.02
A5: 3 | B5: HDFC | C5: 344.29 | D5: 342760.03 | E5: 8.6325995 | F5: 1.23 | G5: 0.45009 | H5: 1.42 | I5: 1.428353 | J5: 0.04
A6: 4 | B6: INFOSYS LTD | C6: 2184.47 | D6: 285007.74 | E6: 7.1780764 | F6: 0.84 | G6: 0.021125 | H6: 4.5 | I6: 1.03058 | J6: 0.04
A7: 5 | B7: ICICI BANK | C7: 1289.42 | D7: 261553.48 | E7: 6.5873679 | F7: 1.33 | G7: 0.309523 | H7: 1.86 | I7: 2.231415 | J7: 0.06
A8: 6 | B8: ITC LTD. | C8: 1225.86 | D8: 257017.5 | E8: 6.4731267 | F8: 0.93 | G8: 0.32215 | H8: 1.27 | I8: 1.634647 | J8: 0.06
A9: 7 | B9: TCS LTD. | C9: 375.24 | D9: 236920.34 | E9: 5.9669686 | F9: -0.01 | G9: 2e-06 | H9: 4.71 | I9: 12.724955 | J9: 0.03
A10: 8 | B10: LARSEN & TOU | C10: 280.55 | D10: 164219.97 | E10: 4.1359701 | F10: 0.91 | G10: 0.28799 | H10: 1.31 | I10: -2.622737 | J10: 0.03
A11: 9 | B11: KOTAK MAH.BK | C11: 954.42 | D11: 163701.41 | E11: 4.1229099 | F11: 0.97 | G11: 0.23906 | H11: 1.54 | I11: 3.840539 | J11: 0.03
A12: 10 | B12: AXIS BANK | C12: 514.47 | D12: 135670.53 | E12: 3.4169367 | F12: 1.16 | G12: 0.284649 | H12: 1.68 | I12: -1.185414 | J12: 0.03
A13: 11 | B13: HIND UNI LT | C13: 216.47 | D13: 125279.99 | E13: 3.1552453 | F13: 0.72 | G13: 0.181606 | H13: 1.31 | I13: 2.702307 | J13: 0.04
A14: 12 | B14: STATE BANK | C14: 892.46 | D14: 116273.1 | E14: 2.9284019 | F14: 1.33 | G14: 0.330687 | H14: 1.8 | I14: -3.304239 | J14: 0.04
... A33: 31 | B33: TATAMTRTDVR | C33: 101.7 | D33: 5196.8904 | E33: 0.13 | F33: 1.38 | G33: 0.178426 | H33: 2.53 | I33: 19.114219 | J33: 0.12
A34: Notes: 1. Beta & R2 are calculated for the trailing 12 months. Beta measures the degree to which any portfolio of stocks is affected as compared to the effect on the market as a whole.
A35: 2. The coefficient of determination (R2) measures the strength of relationship between two variables the return on a security versus that of the market.
A36: 3. Volatility is the standard deviation of the daily returns for the trailing 12 months.
A37: 4. Impact cost is calculated as the difference between actual buy price and ideal buy price, divided by ideal buy price, multiplied by 100. Hence ideal price is calculated as (best buy + best sell)/2.
A38: 5. The above is calculated for a month for the portfolio size of ` 5 lakh. It is calculated for the current month.
A39: Source: BSE.

Sheet 25
A1: Table 25: Component Stocks: Nifty 50 Index during Apr-19
A2: Sl. No | B2: Name of Security | C2: Issued Capital (`Crore) | D2: Free Float Market Capitalisation (` crore) | E2: Weightage (Percent) | F2: Beta | G2: R 2 | H2: Daily Volatility (Percent) | I2: Monthly Return (Percent) | J2: Impact Cost (Percent)
A3: 1 | B3: HDFC Bank Ltd. | C3: 544.66 | D3: 498579.03 | E3: 10.53 | F3: 0.68 | G3: 0.28 | H3: 1 | I3: -0.06 | J3: 0.02
A4: 2 | B4: Reliance Industries Ltd. | C4: 6338.69 | D4: 476740.68 | E4: 10.07 | F4: 1.46 | G4: 0.45 | H4: 1.42 | I4: 2.17 | J4: 0.02
A5: 3 | B5: Housing Development Finance Corporation Ltd. | C5: 343.74 | D5: 329173.86 | E5: 6.95 | F5: 1.22 | G5: 0.43 | H5: 1.28 | I5: 1.36 | J5: 0.01
A6: 4 | B6: Infosys Ltd. | C6: 2184.47 | D6: 285585.91 | E6: 6.03 | F6: 0.59 | G6: 0.1 | H6: 1.21 | I6: 1.01 | J6: 0.02
A7: 5 | B7: ICICI Bank Ltd. | C7: 1288.92 | D7: 262617.28 | E7: 5.55 | F7: 1.31 | G7: 0.3 | H7: 1.58 | I7: 1.75 | J7: 0.03
A8: 6 | B8: ITC Ltd. | C8: 1225.39 | D8: 258490.02 | E8: 5.46 | F8: 0.9 | G8: 0.3 | H8: 0.99 | I8: 1.38 | J8: 0.02
A9: 7 | B9: Tata Consultancy Services Ltd. | C9: 375.24 | D9: 237487.68 | E9: 5.01 | F9: 0.48 | G9: 0.06 | H9: 1.72 | I9: 12.92 | J9: 0.02
A10: 8 | B10: Kotak Mahindra Bank Ltd. | C10: 954.02 | D10: 185190.92 | E10: 3.91 | F10: 0.94 | G10: 0.23 | H10: 0.87 | I10: 3.9 | J10: 0.02
A11: 9 | B11: Larsen & Toubro Ltd. | C11: 280.52 | D11: 166452.82 | E11: 3.51 | F11: 0.92 | G11: 0.3 | H11: 0.89 | I11: -2.65 | J11: 0.02
A12: 10 | B12: Axis Bank Ltd. | C12: 514.25 | D12: 149852.78 | E12: 3.16 | F12: 1.16 | G12: 0.29 | H12: 1.11 | I12: -1.34 | J12: 0.02
A13: 11 | B13: Hindustan Unilever Ltd. | C13: 216.47 | D13: 125559.85 | E13: 2.65 | F13: 0.72 | G13: 0.18 | H13: 0.61 | I13: 2.98 | J13: 0.02
A14: 12 | B14: State Bank of India | C14: 892.46 | D14: 116179.7 | E14: 2.45 | F14: 1.34 | G14: 0.33 | H14: 1.34 | I14: -3.37 | J14: 0.02
... A52: 50 | B52: Bharti Infratel Ltd. | C52: 1849.61 | D52: 22338.27 | E52: 0.47 | F52: 0.29 | G52: 0.01 | H52: 2.68 | I52: -16.23 | J52: 0.03
A53: Notes: 1. Beta & R2 are calculated for the the trailing 12 months. Beta measures the degree to which any portfolio of stocks is affected as compared to the effect on the market as a whole.
A54: 2. The coefficient of determination (R2) measures the strength of relationship between two variables the return on a security versus that of the market.
A55: 3. Volatility is the standard deviation of the daily returns for the the trailing 12 months.
A56: 4. Impact cost is calculated as the difference between actual buy price and ideal buy price, divided by ideal buy price, multiplied by 100. Hence ideal price is calculated as (best buy + best sell)/2.
A57: 5. Impact Cost for Nifty 50 is for a portfolio of Rs. 50 Lakhs and is weightage average impact cost.
A58: Source: NSE.

Sheet 26
A1: Table 26: Component Stocks: SX40 Index
A2: S.No. | B2: Name of Security | C2: Issued Capital (₹ crore) | D2: Free Float Market Capitalisation (₹ crore) | E2: Weightage (Percent) | F2: Beta | G2: R2 | H2: Daily Volatility (Percent) | I2: Monthly Return (Percent) | J2: Impact Cost (Percent) *
A3: 1 | B3: HDFCBANK | C3: 545.00883 | D3: 496164.58 | E3: 11.35 | F3: 0.67 | G3: 0.26 | H3: 0.92 | I3: -0.06 | J3: Na
A4: 2 | B4: RELIANCE | C4: 6338.7505 | D4: 451352 | E4: 10.33 | F4: 1.5 | G4: 0.46 | H4: 1.51 | I4: 2.12 | J4: Na
A5: 3 | B5: HDFC | C5: 344.27049 | D5: 330584.28 | E5: 7.56 | F5: 1.21 | G5: 0.42 | H5: 1.12 | I5: 1.34 | J5: Na
A6: 4 | B6: INFY | C6: 2182.6847 | D6: 284614.34 | E6: 6.51 | F6: 0.67 | G6: 0.12 | H6: 1.19 | I6: 1 | J6: Na
A7: 5 | B7: ICICIBANK | C7: 1289.2879 | D7: 262591.01 | E7: 6.01 | F7: 1.29 | G7: 0.28 | H7: 1.47 | I7: 1.72 | J7: Na
A8: 6 | B8: ITC | C8: 1225.4194 | D8: 260059.87 | E8: 5.95 | F8: 0.92 | G8: 0.31 | H8: 1.01 | I8: 1.36 | J8: Na
A9: 7 | B9: TCS | C9: 375.23847 | D9: 254296.88 | E9: 5.82 | F9: 0.56 | G9: 0.08 | H9: 1.56 | I9: 11.45 | J9: Na
A10: 8 | B10: KOTAKBANK | C10: 954.41781 | D10: 172530.44 | E10: 3.95 | F10: 0.93 | G10: 0.22 | H10: 1.2 | I10: 3.75 | J10: Na
A11: 9 | B11: LT | C11: 280.49146 | D11: 165901.87 | E11: 3.8 | F11: 0.94 | G11: 0.3 | H11: 1.17 | I11: -2.73 | J11: Na
A12: 10 | B12: AXISBANK | C12: 514.18478 | D12: 151474.75 | E12: 3.47 | F12: 1.16 | G12: 0.28 | H12: 1.26 | I12: -1.36 | J12: Na
A13: 11 | B13: HINDUNILVR | C13: 216.47044 | D13: 124842.24 | E13: 2.86 | F13: 0.73 | G13: 0.18 | H13: 0.77 | I13: 2.9 | J13: Na
A14: 12 | B14: SBIN | C14: 892.46115 | D14: 116877 | E14: 2.67 | F14: 1.32 | G14: 0.31 | H14: 1.52 | I14: -3.48 | J14: Na
... A42: 40 | B42: ZEEL | C42: 96.04665 | D42: 24256.154 | E42: 0.55 | F42: 0.78 | G42: 0.04 | H42: 3 | I42: -2.98 | J42: Na
A43: Notes:
A44: 1. Market Cap, Beta & R2 as on the last day of the month
A45: 2. Beta & R2 are calculated for the trailing 12 months
A46: 3. Volatility for the current month
A47: 4. *Since there is no trading in the SX40 constituents, the Impact Cost for the given stocks is NIL.
A48: Source: MSEI.

Sheet 27
A1: Table 27: Advances/Declines in Cash Segment of BSE, NSE and MSEI
A2: Year/ Month | B2: BSE | E2: NSE | H2: MSEI
B3: Advances | C3: Declines | D3: Advance/Decline Ratio | E3: Advances | F3: Declines | G3: Advance/Decline Ratio | H3: Advances | I3: Declines | J3: Advance/Decline Ratio
A4: 2018-19 | B4: 1156 | C4: 2730 | D4: 0.42344322 | E4: 585 | F4: 1294 | G4: 0.45 | H4: 2 | I4: 5 | J4: 0.4
A5: 2019-20$ | B5: 930 | C5: 2621 | D5: 0.3548264 | E5: 353 | F5: 1434 | G5: 0.25 | H5: 2 | I5: 2 | J5: 1
A6: Apr-19 | B6: 1541 | C6: 1921 | D6: 0.80218636 | E6: 879 | F6: 1040 | G6: 0.85 | H6: 2 | I6: 2 | J6: 1
A7: Note: Advance/Decline is calculated based on the average price methodology.
A8: $ indicates as on April 30, 2019
A9: Source: BSE, NSE and MSEI.

Sheet 28
A1: Table 28: Trading Frequency in Cash Segment of BSE, NSE and MSEI
A2: Month | B2: BSE | E2: NSE | H2: MSEI
B3: No. of Companies Listed | C3: No. of Companies Traded | D3: Percent of Traded to Listed | E3: No. of Companies Listed | F3: No. of Companies Traded | G3: Percent of Traded to Listed | H3: No. of Companies Listed | I3: No. of Companies Traded | J3: Percent of Traded to Listed
A4: 2018-19 | B4: 5262 | C4: 4086 | D4: 77.651083 | E4: 1931 | F4: 1922 | G4: 99.53392 | H4: 287 | I4: 8 | J4: 2.7874564
A5: 2019-20$ | B5: 5282 | C5: 3580 | D5: 67.777357 | E5: 1938 | F5: 1856 | G5: 95.768834 | H5: 286 | I5: 6 | J5: 2.0979021
A6: Apr-19 | B6: 5282 | C6: 3580 | D6: 67.777357 | E6: 1938 | F6: 1856 | G6: 95.768834 | H6: 286 | I6: 6 | J6: 2.0979021
A7: $ indicates as on April 30,2019
A8: Source: BSE, NSE and MSEI.

Sheet 29
A1: Table 29: Daily Volatility of Major Indices (percent)
A2: Year / Month | B2: BSE Sensex | C2: BSE 100 | D2: BSE 500 | E2: Nifty 50 | F2: Nifty Next 50 | G2: Nifty 500 | H2: SX40
A3: 2018-19 | B3: 0.76505508 | C3: 0.79260673 | D3: 0.80214609 | E3: 0.78237731 | F3: 1.0209709 | G3: 0.80626923 | H3: 0.77
A4: 2019-20$ | B4: 0.68796438 | C4: 0.64456652 | D4: 0.61263988 | E4: 0.66285354 | F4: 0.57229388 | G4: 0.60203805 | H4: 0.71
A5: Apr-19 | B5: 0.68796438 | C5: 0.64456652 | D5: 0.61263988 | E5: 0.66285354 | F5: 0.57229388 | G5: 0.60203805 | H5: 0.71
A6: Note: Volatility is calculated as the standard deviation of the natural log of daily returns in indices for the respective period.
A7: $ indicates as on April 30,2019
A8: Source: BSE, MSEI and NSE.

Sheet 30
A1: Table 30: Percentage Share of Top ‘N’ Securities/Members in Turnover of Cash Segment (percent)
A2: Year/ Month | B2: BSE | G2: NSE | L2: MSEI
A3: Top | B3: 5 | C3: 10 | D3: 25 | E3: 50 | F3: 100 | G3: 5 | H3: 10 | I3: 25 | J3: 50 | K3: 100 | L3: 5 | M3: 10 | N3: 25 | O3: 50 | P3: 100
A4: Securities
A5: 2018-19 | B5: 9.529 | C5: 16.1709 | D5: 31.0552 | E5: 44.2911 | F5: 60.2394 | G5: 11.68 | H5: 20.43 | I5: 36.67 | J5: 52.57 | K5: 70.93 | L5: 98.9 | M5: 100 | N5: 100 | O5: 100 | P5: 100
A6: 2019-20$ | B6: 16.79 | C6: 26.8901 | D6: 42.9178 | E6: 56.3117 | F6: 70.2505 | G6: 14.92 | H6: 24.97 | I6: 43 | J6: 59.47 | K6: 76.69 | L6: 99.47 | M6: 100 | N6: 100 | O6: 100 | P6: 100
A7: Apr-19 | B7: 16.79 | C7: 26.8901 | D7: 42.9178 | E7: 56.3117 | F7: 70.2505 | G7: 14.92 | H7: 24.97 | I7: 43 | J7: 59.47 | K7: 76.69 | L7: 99.47 | M7: 100 | N7: 100 | O7: 100 | P7: 100
A8: Members
A9: 2018-19 | B9: 24.2 | C9: 38.4 | D9: 61 | E9: 73.5 | F9: 84.5 | G9: 22.47 | H9: 34.34 | I9: 54.6 | J9: 72.37 | K9: 85.69 | L9: 94.71 | M9: 100 | N9: 100 | O9: 100 | P9: Na
A10: 2019-20$ | B10: 31.24 | C10: 46.01 | D10: 62.89 | E10: 74.51 | F10: 84.49 | G10: 24.97 | H10: 37.18 | I10: 57.29 | J10: 74.1 | K10: 86.64 | L10: 88.28 | M10: 100 | N10: 100 | O10: 100 | P10: Na
A11: Apr-19 | B11: 31.24 | C11: 46.01 | D11: 62.89 | E11: 74.51 | F11: 84.49 | G11: 24.97 | H11: 37.18 | I11: 57.29 | J11: 74.1 | K11: 86.64 | L11: 88.28 | M11: 100 | N11: 100 | O11: 100 | P11: Na
A12: Notes: 1. Data for Top N scrips has been compiled for all markets except Auction market & Retail Debt Market and includes series EQ, BE,BT, BL and IL.
A13: 2. During the month only 57 members were permitted to trade.
A14: $ indicates as on April 30,2019
A15: Source: BSE, NSE and MSEI.

Sheet 31
A1: Table 31: Settlement Statistics for Cash Segment of BSE
A2: Year / Month | B2: No. of Trades(Lakh) | C2: Traded Quantity (Lakh) | D2: Delivered Quantity (Lakh) | E2: Percent of Delivered Quantity to Traded Quantity | F2: Turnover (` crore) | G2: Delivered Value (` crore) | H2: Percent of Delivered Value to Total Turnover | I2: Delivered Quantity in Demat Mode (Lakh) | J2: Percent of Demat Delivered Quantity to Total Delivered Quantity | K2: Delivered Value in Demat Mode (` crore) | L2: Percent of Demat Delivered Value to Total Delivered Value | M2: Short Delivery (Auctioned quantity) (Lakh) | N2: Percent of Short Delivery to Delivery Quantity | O2: Funds Pay-in (` crore) | P2: Securities Pay-in (` crore) | Q2: Settlement Guarantee Fund (`crore)
A3: 2018-19 | B3: 3145.2411 | C3: 518108 | D3: 195611.7 | E3: 37.528772 | F3: 775589.75 | G3: 261208.29 | H3: 33.097801 | I3: 195277.89 | J3: 99.814042 | K3: 261207.8 | L3: 99.994167 | M3: 458.18739 | N3: 0.22265529 | O3: 109583.71 | P3: 194997.75 | Q3: 207.14
A4: 2019-20$ | B4: 254.76076 | C4: 59515 | D4: 49993.686 | E4: 84.001825 | F4: 56860.88 | G4: 19548.391 | H4: 34.379333 | I4: 16965.053 | J4: 33.934392 | K4: 19191.226 | L4: 98.172918 | M4: 30.62797 | N4: 0.18053565 | O4: 10404.408 | P4: 19570.154 | Q4: 208.35
A5: Apr-19 | B5: 254.76076 | C5: 59515 | D5: 49993.686 | E5: 84.001825 | F5: 56860.88 | G5: 19548.391 | H5: 34.379333 | I5: 16965.053 | J5: 33.934392 | K5: 19191.226 | L5: 98.172918 | M5: 30.62797 | N5: 0.18053565 | O5: 10404.408 | P5: 19570.154 | Q5: 208.35
A6: $ indicates as on April 30,2019
A7: Source: BSE.

Sheet 32
A1: Table 32: Settlement Statistics for Cash Segment of NSE
A2: Year / Month | B2: No. of Trades(Lakh) | C2: Traded Quantity (Lakh) | D2: Delivered Quantity (Lakh) | E2: Percent of Delivered Quantity to Traded Quantity | F2: Turnover (` crore) | G2: Delivered Value (` crore) | H2: Percent of Delivered Value to Total Turnover | I2: Delivered Quantity in Demat Mode (Lakh) | J2: Percent of Demat Delivered Quantity to Total Delivered Quantity | K2: Delivered Value in Demat Mode (` crore) | L2: Percent of Demat Delivered Value to Total Delivered Value | M2: Short Delivery (Auctioned quantity) (Lakh) | N2: Percent of Short Delivery to Delivery Quantity | O2: Funds Pay-in (` crore) | P2: Securities Pay-in (` crore) | Q2: Settlement Guarantee Fund (`crore)
A3: 2018-19 | B3: 28452.85 | C3: 3668649.1 | D3: 845400.34 | E3: 23.04 | F3: 7912284.5 | G3: 1950906.3 | H3: 24.66 | I3: 844261.48 | J3: 100 | K3: 1949508.1 | L3: 100 | M3: 1138.86 | N3: 0.13 | O3: 533294.54 | P3: 1950906.3 | Q3: 270.69
A4: 2019-20$ | B4: 2178.6753 | C4: 318767.13 | D4: 83715.624 | E4: 26.262314 | F4: 660248.73 | G4: 164990.23 | H4: 24.989102 | I4: 83612.943 | J4: 100 | K4: 164854.61 | L4: 100 | M4: 102.68078 | N4: 0.12265426 | O4: 43313.93 | P4: 164990.23 | Q4: 273.14
A5: Apr-19 | B5: 2178.6753 | C5: 318767.13 | D5: 83715.624 | E5: 26.262314 | F5: 660248.73 | G5: 164990.23 | H5: 24.989102 | I5: 83612.943 | J5: 100 | K5: 164854.61 | L5: 100 | M5: 102.68078 | N5: 0.12265426 | O5: 43313.93 | P5: 164990.23 | Q5: 273.14
A6: Settlement Statistics for settlement type N, excluding CM Series IL & BL
A7: $ indicates as on April 30,2019
A8: Source: NSE.

Sheet 33
A1: Table 33: Settlement Statistics for Cash Segment of MSEI
A2: Month Sorting | B2: No. of Trades(Lakh) | C2: Traded Quantity (Lakh) | D2: Delivered Quantity (Lakh) | E2: Percent of Delivered Quantity to Traded Quantity | F2: Turnover (₹ crore) | G2: Delivered Value (₹ crore) | H2: Percent of Delivered Value to Total Turnover | I2: Delivered Quantity in Demat Mode (Lakh) | J2: Percent of Demat Delivered Quantity to Total Delivered Quantity | K2: Delivered Value in Demat Mode (₹ crore) | L2: Percent of Demat Delivered Value to Total Delivered Value | M2: Funds Pay-in (₹ crore) | N2: Securities Pay-in (₹ crore) | O2: Settlement Guarantee Fund(₹ crore)
A3: 2018-19 | B3: 0.01915 | C3: 14.16864 | D3: 14.16864 | E3: 100 | F3: 30.293252 | G3: 30.293252 | H3: 100 | I3: 14.16864 | J3: 100 | K3: 30.293252 | L3: 100 | M3: 30.293252 | N3: 30.293252 | O3: 0.32
A4: 2019-20$ | B4: 0.00227 | C4: 3.82974 | D4: 3.82974 | E4: 100 | F4: 7.4556996 | G4: 7.4556996 | H4: 100 | I4: 3.82974 | J4: 100 | K4: 7.4556996 | L4: 100 | M4: 7.4556996 | N4: 7.4556996 | O4: 0.32
A5: Apr-19 | B5: 0.00227 | C5: 3.82974 | D5: 3.82974 | E5: 100 | F5: 7.4556996 | G5: 7.4556996 | H5: 100 | I5: 3.82974 | J5: 100 | K5: 7.4556996 | L5: 100 | M5: 7.4556996 | N5: 7.4556996 | O5: 0.32
A6: $ indicates as on April 30, 2019
A7: Source: MSEI.

Sheet 34
A1: Table 34: Trends in Equity Derivatives Segment at BSE (Turnover in Notional Value)
A2: Year/ Month | B2: No. of Trading Days | C2: Index Futures | E2: Stock Futures | G2: Index Options | K2: Stock Options | O2: Total | Q2: Open Interest at the end of Month
G3: Call | I3: Put | K3: Call | M3: Put
C4: No. of Contracts | D4: Turnover (` crore) | E4: No. of Contracts | F4: Turnover (` crore) | G4: No. of Contracts | H4: Turnover (` crore) | I4: No. of Contracts | J4: Turnover (` crore) | K4: No. of Contracts | L4: Turnover (` crore) | M4: No. of Contracts | N4: Turnover (` crore) | O4: No. of Contracts | P4: Turnover (` crore) | Q4: No. of contracts | R4: Turnover (` crore)
A5: 2018-19 | B5: 248 | C5: 438 | D5: 39.15837 | E5: 271 | F5: 17.779123 | G5: 19158 | H5: 1308.5017 | I5: 11298 | J5: 884.62804 | K5: 2 | L5: 0.07568 | M5: 0 | N5: 0 | O5: 31167 | P5: 2250.1429 | Q5: 9 | R5: 0.67341037
A6: 2019-20$ | B6: 19 | C6: 7 | D6: 0.68431138 | E6: 51 | F6: 3.5252402 | G6: 0 | H6: 0 | I6: 0 | J6: 0 | K6: 0 | L6: 0 | M6: 0 | N6: 0 | O6: 58 | P6: 4.2095516 | Q6: 6 | R6: 0.47
A7: Apr-19 | B7: 19 | C7: 7 | D7: 0.68431138 | E7: 51 | F7: 3.5252402 | G7: 0 | H7: 0 | I7: 0 | J7: 0 | K7: 0 | L7: 0 | M7: 0 | N7: 0 | O7: 58 | P7: 4.2095516 | Q7: 6 | R7: 0.47
A8: Note: 1. Notional Turnover = (Strike Price + Premium) * Quantity.
A9: $ indicates as on April 30,2019
A10: Source: BSE.

Sheet 35
A1: Table 35: Trends in Equity Derivatives Segment at NSE (Turnover in Notional Value)
A2: Year/ Month | B2: No. of Trading Days | C2: Index Futures | E2: Stock Futures | G2: Index Options | K2: Stock Options | O2: Total | Q2: Open Interest at the end of Month
G3: Call | I3: Put | K3: Call | M3: Put
C4: No. of Contracts | D4: Turnover (` crore) | E4: No. of Contracts | F4: Turnover (` crore) | G4: No. of Contracts | H4: Turnover (` crore) | I4: No. of Contracts | J4: Turnover (` crore) | K4: No. of Contracts | L4: Turnover (` crore) | M4: No. of Contracts | N4: Turnover (` crore) | O4: No. of Contracts | P4: Turnover (` crore) | Q4: No. of Contracts | R4: Turnover (` crore)
A5: 2018-19 | B5: 248 | C5: 69824522 | D5: 5568914.4 | E5: 255533869 | F5: 16147011 | G5: 1391027617 | H5: 1.0772633e+08 | I5: 1261429870 | J5: 95576078 | K5: 123510308 | L5: 8517920.5 | M5: 63476234 | N5: 4064454.4 | O5: 3164802420 | P5: 237600705 | Q5: 4038916 | R5: 286402.85
A6: 2019-20$ | B6: 19 | C6: 5521413 | D6: 406219.34 | E6: 18819091 | F6: 1159128.2 | G6: 161093858 | H6: 10860276 | I6: 137719004 | J6: 9170370.4 | K6: 9936612 | L6: 651294.77 | M6: 5037643 | N6: 307998.01 | O6: 338127621 | P6: 22555286 | Q6: 4397035 | R6: 300027.62
A7: Apr-19 | B7: 19 | C7: 5521413 | D7: 406219.34 | E7: 18819091 | F7: 1159128.2 | G7: 161093858 | H7: 10860276 | I7: 137719004 | J7: 9170370.4 | K7: 9936612 | L7: 651294.77 | M7: 5037643 | N7: 307998.01 | O7: 338127621 | P7: 22555286 | Q7: 4397035 | R7: 300027.62
A8: Note: 1. Notional Turnover = (Strike Price + Premium) * Quantity.
A9: $ indicates as on April 30,2019
A10: Source: NSE.

Sheet 36
A1: Table 36: Settlement Statistics in Equity Derivatives Segment at BSE and NSE (` crore)
A2: Year/ Month | B2: BSE | H2: NSE
B3: Index/Stock Futures | D3: Index/Stock Options | F3: Total | G3: Settlement Gurantee Fund | H3: Index/Stock Futures | J3: Index/Stock Options | L3: Total | M3: Settlement Gurantee Fund
B4: MTM Settlement | C4: Final Settlement | D4: Premium Settlement | E4: Exercise Settlement | H4: MTM Settlement | I4: Final Settlement | J4: Premium Settlement | K4: Exercise Settlement
A5: 2018-19 | B5: 0.98 | C5: 0.08 | D5: 8.67 | E5: 0.05 | F5: 9.78 | G5: 19.43 | H5: 136640.06 | I5: 2754.22 | J5: 19252.85 | K5: 2534.91 | L5: 161182.04 | M5: 1911.63
A6: 2019-20$ | B6: 0.15 | C6: 0.02 | D6: 0 | E6: 0 | F6: 0.17 | G6: 19.54 | H6: 7864.19 | I6: 114.9 | J6: 1522.91 | K6: 93.85 | L6: 9595.85 | M6: 1936.43
A7: Apr-19 | B7: 0.15 | C7: 0.02 | D7: 0 | E7: 0 | F7: 0.17 | G7: 19.54 | H7: 7864.19 | I7: 114.9 | J7: 1522.91 | K7: 93.85 | L7: 9595.85 | M7: 1936.43
A8: $ indicates as on April 30,2019
A9: Source: BSE and NSE

Sheet 37
A1: Table 37: Category-wise Share of Turnover & Open Interest in Equity Derivative Segment of BSE
A2: Year/Month | B2: Percentage Share in Turnover | G2: Percentage Share in Open Interest
B3: Pro | C3: FPI | D3: Mutual Funds | E3: Banks | F3: Others | G3: Pro | H3: FPI | I3: Mutual Funds | J3: Banks | K3: Others
A4: 2018-19 | B4: 2 | C4: 0 | D4: 0 | E4: 0 | F4: 98 | G4: 0 | H4: 0 | I4: 0 | J4: 0 | K4: 100
A5: 2019-20$ | B5: 16.26 | C5: 0 | D5: 0 | E5: 0 | F5: 83.74 | G5: 0 | H5: 0 | I5: 0 | J5: 0 | K5: 100
A6: Apr-19 | B6: 16.26 | C6: 0 | D6: 0 | E6: 0 | F6: 83.74 | G6: 0 | H6: 0 | I6: 0 | J6: 0 | K6: 100
A7: $ indicates as on April 30,2019
A8: Source: BSE.

Sheet 38
A1: Table 38: Category-wise Share of Turnover & Open Interest in Equity Derivative Segment of NSE
A2: Year/Month | B2: Percentage Share in Turnover | G2: Percentage Share in Open Interest
B3: Pro | C3: FPIs | D3: Mutual Funds | E3: Banks | F3: Others | G3: Pro | H3: FPIs | I3: Mutual Funds | J3: Banks | K3: Others
A4: 2018-19 | B4: 37.84 | C4: 13.58 | D4: 0.42 | E4: 0 | F4: 48.16 | G4: 13.72 | H4: 29.83 | I4: 13.19 | J4: 0 | K4: 43.25
A5: 2019-20$ | B5: 32.86 | C5: 19.28 | D5: 0.34 | E5: 0 | F5: 47.52 | G5: 13.53 | H5: 26.86 | I5: 12.8 | J5: 0 | K5: 46.81
A6: Apr-19 | B6: 32.86 | C6: 19.28 | D6: 0.34 | E6: 0 | F6: 47.52 | G6: 13.53 | H6: 26.86 | I6: 12.8 | J6: 0 | K6: 46.81
A7: $ indicates as on April 30,2019
A8: Source: NSE.

Sheet 39
A1: Table 39: Instrument-wise Turnover in Index Derivatives at BSE
A2: Turnover (in Percentage)
A3: Year/Month | B3: BSE 30 SENSEX | C3: BSE SENSEX 50 | D3: BSE BANKEX | E3: BSE OIL & GAS INDEX | F3: BSE TECK INDEX | G3: BSE100 | H3: HANG SENG Index Futures | I3: MICEX Index Futures | J3: FTSE/JSE Top 40 Futures | K3: IBOVESPA Futures
A4: 2018-19 | B4: 41.32 | C4: 0 | D4: 58.68 | E4: 0 | F4: 0 | G4: 0 | H4: 0 | I4: 0 | J4: 0 | K4: 0
A5: 2019-20$ | B5: 100 | C5: 0 | D5: 0 | E5: 0 | F5: 0 | G5: 0 | H5: 0 | I5: 0 | J5: 0 | K5: 0
A6: Apr-19 | B6: 100 | C6: 0 | D6: 0 | E6: 0 | F6: 0 | G6: 0 | H6: 0 | I6: 0 | J6: 0 | K6: 0
A7: $ indicates as on April 30,2019
A8: Source: BSE.

Sheet 40
A1: Table 40: Instrument-wise Turnover in Index Derivatives at NSE
A2: Turnover (in Percentage)
A3: Year/Month | B3: NIFTY | C3: NIFTYIT | D3: BANKNIFTY | E3: NIFTYMID50 | F3: NIFTYPSE | G3: NIFTYINFRA | H3: FTSE100 | I3: S&P500 | J3: DJIA | K3: India VIX | L3: NIFTYCPSE
A4: 2018-19 | B4: 26.234649 | C4: 0.003855915 | D4: 73.75893 | E4: 0.002828893 | F4: 1e-06 | G4: 0 | H4: 8.5e-08 | I4: 0 | J4: 0 | K4: 0 | L4: 4.01e-07
A5: 2019-20$ | B5: 32.68824 | C5: 0.002977 | D5: 67.308783 | E5: 0 | F5: 0 | G5: 0 | H5: 0 | I5: 0 | J5: 0 | K5: 0 | L5: 0
A6: Apr-19 | B6: 32.68824 | C6: 0.002977 | D6: 67.308783 | E6: 0 | F6: 0 | G6: 0 | H6: 0 | I6: 0 | J6: 0 | K6: 0 | L6: 0
A7: $ indicates as on April 30,2019
A8: Source: NSE.

Sheet 41
A1: Table 41: Trends in Currency Derivatives Segment at BSE
A2: Year/ Month | B2: No. of Trading Days | C2: Currency Futures | E2: Currency Options | I2: Total | K2: Open Interest at the end of the Month
E3: Call | G3: Put
C4: No. of Contracts | D4: Turnover (` crore) | E4: No. of Contracts | F4: Turnover (` crore) | G4: No. of Contracts | H4: Turnover (` crore) | I4: No. of Contracts | J4: Turnover (` crore) | K4: No. of Contracts | L4: Value (` crore)
A5: 2018-19 | B5: 243 | C5: 456884165 | D5: 3206488.6 | E5: 241869262 | F5: 1719119.9 | G5: 353698730 | H5: 2426665.9 | I5: 1052452157 | J5: 7352274.4 | K5: 712162 | L5: 4929.4031
A6: 2019-20$ | B6: 18 | C6: 28454552 | D6: 198227.25 | E6: 27648067 | F6: 196542.51 | G6: 27200048 | H6: 185922.52 | I6: 83302667 | J6: 580692.29 | K6: 1277029 | L6: 8920.27
A7: Apr-19 | B7: 18 | C7: 28454552 | D7: 198227.25 | E7: 27648067 | F7: 196542.51 | G7: 27200048 | H7: 185922.52 | I7: 83302667 | J7: 580692.29 | K7: 1277029 | L7: 8920.27
A8: $ indicates as on April 30,2019
A9: Source: BSE

Sheet 42
A1: Table 42: Trends in Currency Derivatives Segment at NSE
A2: Year/ Month | B2: No. of Trading Days | C2: Currency Futures | E2: Currency Options | I2: Total | K2: Open Interest at the end of Month
C3: No. of Contracts | D3: Turnover (` crore) | E3: Call | G3: Put | I3: No. of Contracts | J3: Turnover (` crore) | K3: No. of Contracts | L3: Value (` crore)
E4: No. of Contracts | F4: Turnover (` crore) | G4: No. of Contracts | H4: Turnover (` crore)
A5: 2018-19 | B5: 243 | C5: 650024870 | D5: 4654927.1 | E5: 275919964 | F5: 1956019.7 | G5: 272439387 | H5: 1907404.5 | I5: 1198384221 | J5: 8518351.2 | K5: 4205566 | L5: 29351.446
A6: 2019-20$ | B6: 18 | C6: 50944880 | D6: 361284.9 | E6: 25110750 | F6: 175702.56 | G6: 25140409 | H6: 174367.63 | I6: 101196039 | J6: 711355.08 | K6: 5062681 | L6: 35527.744
A7: Apr-19 | B7: 18 | C7: 50944880 | D7: 361284.9 | E7: 25110750 | F7: 175702.56 | G7: 25140409 | H7: 174367.63 | I7: 101196039 | J7: 711355.08 | K7: 5062681 | L7: 35527.744
A8: Notes: 1. Trading Value :- For Futures, Value of contract = Traded Qty*Traded Price. 2. For Options, Value of contract = Traded Qty*(Strike Price+Traded Premium)
A9: $ indicates as on April 30,2019
A10: Source: NSE.

Sheet 43
A1: Table 43: Trends in Currency Derivatives Segment at MSEI
A2: Year/ Month | B2: No. of Trading Days | C2: Currency Futures | E2: Currency Options | I2: Total | K2: Open Interest at the end of Month
C3: No. of Contracts | D3: Turnover (` crore) | E3: Call | G3: Put | I3: No. of Contracts | J3: Turnover (` crore) | K3: No. of Contracts | L3: Value (` crore)
E4: No. of Contracts | F4: Turnover (` crore) | G4: No. of Contracts | H4: Turnover (` crore)
A5: 2018-19 | B5: 243 | C5: 5499701 | D5: 38194.64 | E5: 574634 | F5: 4082.9041 | G5: 697331 | H5: 4960.9747 | I5: 6771666 | J5: 47238.518 | K5: 18715 | L5: 130.15286
A6: 2019-20$ | B6: 18 | C6: 243494 | D6: 1704.5449 | E6: 62239 | F6: 444.06509 | G6: 90537 | H6: 631.72794 | I6: 396270 | J6: 2780.3379 | K6: 19412 | L6: 141.17954
A7: Apr-19 | B7: 18 | C7: 243494 | D7: 1704.5449 | E7: 62239 | F7: 444.06509 | G7: 90537 | H7: 631.72794 | I7: 396270 | J7: 2780.3379 | K7: 19412 | L7: 141.17954
A8: $ indicates as on April 30,2019
A9: Source: MSEI

Sheet 44
A1: Table 44: Settlement Statistics of Currency Derivatives Segment (` crore)
A2: Year/ Month | B2: BSE | F2: Total | G2: NSE | K2: Total | L2: MSEI | P2: Total
B3: Currency Futures | D3: Currency Options | G3: Currency Futures | I3: Currency Options | L3: Currency Futures | N3: Currency Options
B4: MTM Settlement | C4: Final Settlement | D4: Premium Settlement | E4: Exercise Settlement | G4: MTM Settlement | H4: Final Settlement | I4: Premium Settlement | J4: Exercise Settlement | L4: MTM Settlement | M4: Final Settlement | N4: Premium Settlement | O4: Exercise Settlement
A5: 2018-19 | B5: 5970.05 | C5: 191.46 | D5: 3565.27 | E5: 154.97 | F5: 9881.75 | G5: 8260.464 | H5: 292.40325 | I5: 1286.8978 | J5: 643.41508 | K5: 10483.18 | L5: 125.37569 | M5: 6.8401983 | N5: 0.555969 | O5: 0.68199744 | P5: 133.45385
A6: 2019-20$ | B6: 363.16 | C6: 6.08 | D6: 403.39 | E6: 6.8 | F6: 779.43 | G6: 512.90147 | H6: 6.432021 | I6: 102.97739 | J6: 25.654563 | K6: 647.96544 | L6: 14.89 | M6: 0.22280344 | N6: 0.01516775 | O6: 0.0010549 | P6: 15.129026
A7: Apr-19 | B7: 363.16 | C7: 6.08 | D7: 403.39 | E7: 6.8 | F7: 779.43 | G7: 512.90147 | H7: 6.432021 | I7: 102.97739 | J7: 25.654563 | K7: 647.96544 | L7: 14.89 | M7: 0.22280344 | N7: 0.01516775 | O7: 0.0010549 | P7: 15.129026
A8: $ indicates as on April 30,2019
A9: Source: BSE, NSE and MSEI.

Sheet 45
A1: Table 45: Instrument-wise Turnover in Currency Derivative Segment of BSE
A2: Year/Month | B2: Turnover (` crore) | I2: Open Interest as on last day of the month (in lots)
B3: USDINR | C3: EURINR | D3: GBPINR | E3: JPYINR | F3: EURUSD | G3: GBPUSD | H3: USDJPY | I3: USDINR | J3: EURINR | K3: GBPINR | L3: JPYINR | M3: EURUSD | N3: GBPUSD | O3: USDJPY
A4: 2018-2019 | B4: 7336635.9 | C4: 5354.2229 | D4: 4940.5534 | E4: 1322.2592 | F4: 2712.9962 | G4: 1275.3717 | H4: 33.1141 | I4: 709594 | J4: 873 | K4: 1332 | L4: 354 | M4: 0 | N4: 9 | O4: 0
A5: 2019-20$ | B5: 580467.68 | C5: 46.114839 | D5: 138.95065 | E5: 39.54 | F5: 0 | G5: 0 | H5: 0 | I5: 1275372 | J5: 308 | K5: 946 | L5: 403 | M5: 0 | N5: 0 | O5: 0
A6: Apr-19 | B6: 580467.68 | C6: 46.114839 | D6: 138.95065 | E6: 39.54 | F6: 0 | G6: 0 | H6: 0 | I6: 1275372 | J6: 308 | K6: 946 | L6: 403 | M6: 0 | N6: 0 | O6: 0
A7: 1. USDINR includes Futures and options both other currencys have only futures till February 26, 2018.
A8: 2. All Products include both Futures & options from February 27, 2018 onwards.
A9: 3. EURUSD, GBPUSD, USDJPY wer launched in Feb 2018
A10: $ indicates as on April 30,2019
A11: Source: BSE

Sheet 46
A1: Table 46: Instrument-wise Turnover in Currency Derivatives of NSE
A2: Year/Month | B2: Turnover ( ` crore) | I2: Open Interest as on last day of the month ( in lots)
B3: USDINR | C3: EURINR | D3: GBPINR | E3: JPYINR | F3: EURUSD | G3: GBPUSD | H3: USDJPY | I3: USDINR | J3: EURINR | K3: GBPINR | L3: JPYINR | M3: EURUSD | N3: GBPUSD | O3: USDJPY
A4: 2018-19$ | B4: 7978933.8 | C4: 176061.27 | D4: 226751.72 | E4: 59106.091 | F4: 42661.716 | G4: 33643.822 | H4: 1192.8246 | I4: 4059718 | J4: 50501 | K4: 37698 | L4: 21801 | M4: 33796 | N4: 1978 | O4: 74
A5: 2019-20 | B5: 673980.52 | C5: 10092.261 | D5: 21981.23 | E5: 3519.8798 | F5: 897.44538 | G5: 872.66995 | H5: 11.079929 | I5: 4911962 | J5: 49395 | K5: 32413 | L5: 23666 | M5: 42550 | N5: 2631 | O5: 64
A6: Apr-19 | B6: 673980.52 | C6: 10092.261 | D6: 21981.23 | E6: 3519.8798 | F6: 897.44538 | G6: 872.66995 | H6: 11.079929 | I6: 4911962 | J6: 49395 | K6: 32413 | L6: 23666 | M6: 42550 | N6: 2631 | O6: 64
A7: 1. Cross Currency was introduced wef Feb 27, 2018
A8: 2. Options contracts on EURINR,GBPINR,JPYINR were introduced wef Feb 27, 2018
A9: $ indicates as on April 30,2019
A10: Source: NSE.

Sheet 47
A1: Table 47: Instrument-wise Turnover in Currency Derivative Segment of MSEI
A2: Year/Month | B2: Turnover (` crore) | F2: Open Interest as on last day of the month (in lots)
B3: USDINR | C3: EURINR | D3: GBPINR | E3: JPYINR | F3: USDINR | G3: EURINR | H3: GBPINR | I3: JPYINR
A4: 2018-19 | B4: 45388.394 | C4: 682.56191 | D4: 1144.1231 | E4: 21.812767 | F4: 18649 | G4: 53 | H4: 7 | I4: 6
A5: 2019-20$ | B5: 2659.6614 | C5: 60.362018 | D5: 59.801301 | E5: 0.5131315 | F5: 16184 | G5: 1593 | H5: 1629 | I5: 6
A6: Apr-19 | B6: 2659.6614 | C6: 60.362018 | D6: 59.801301 | E6: 0.5131315 | F6: 16184 | G6: 1593 | H6: 1629 | I6: 6
A7: Data includes Notional Value for Options
A8: Excludes data of Interest Rate Futures
A9: $ indicates as on April 30,2019
A10: Source: MSEI

Sheet 48
A1: Table 48: Maturity-wise Turnover in Currency Derivative Segment of BSE (` crore)
A2: Year/Month | B2: Currency Futures | F2: Currency Options
B3: 1 Month | C3: 2 Month | D3: 3 Month | E3: > 3 Months | F3: 1 Month | G3: 2 Month | H3: 3 Month | I3: > 3 Months
A4: 2018-19 | B4: 2821842.2 | C4: 328321.59 | D4: 9826.4511 | E4: 1918.3599 | F4: 3701091.9 | G4: 315307.15 | H4: 1160.0513 | I4: 127.1642
A5: 2019-20$ | B5: 169144.15 | C5: 24434.401 | D5: 317.7254 | E5: 10.6563 | F5: 327257.38 | G5: 27355.288 | H5: 3.9959 | I5: 0
A6: Apr-19 | B6: 169144.15 | C6: 24434.401 | D6: 317.7254 | E6: 10.6563 | F6: 327257.38 | G6: 27355.288 | H6: 3.9959 | I6: 0
A7: $ indicates as on April 30,2019
A8: Source: BSE

Sheet 49
A1: Table 49: Maturity-wise Turnover in Currency Derivative Segment of NSE (` crore)
A2: Year/Month | B2: Currency Future | F2: Currency Options
B3: 1 Month | C3: 2 Month | D3: 3 Month | E3: > 3 Months | F3: 1 Month | G3: 2 Month | H3: 3 Month | I3: > 3 Months
A4: 2018-19 | B4: 3719230 | C4: 828483.43 | D4: 70716.607 | E4: 36497.054 | F4: 2646030.7 | G4: 578570.97 | H4: 242227.87 | I4: 396594.59
A5: 2019-20$ | B5: 277112.52 | C5: 74400.989 | D5: 6549.2537 | E5: 3222.1359 | F5: 189409.03 | G5: 47929.714 | H5: 42277.963 | I5: 70453.478
A6: Apr-19 | B6: 277112.52 | C6: 74400.989 | D6: 6549.2537 | E6: 3222.1359 | F6: 189409.03 | G6: 47929.714 | H6: 42277.963 | I6: 70453.478
A7: $ indicates as on April 30,2019
A8: Source: NSE.

Sheet 50
A1: Table 50: Maturity-wise Turnover in Currency Derivative Segment of MSEI (` crore)
A2: Year/Month | B2: Currency Future | F2: Currency Options
B3: 1 Month | C3: 2 Month | D3: 3 Month | E3: > 3 Months | F3: 1 Month | G3: 2 Month | H3: 3 Month | I3: > 3 Months
A4: 2018-19 | B4: 33138.897 | C4: 4977.6412 | D4: 55.156287 | E4: 22.945404 | F4: 5702.8547 | G4: 3164.6336 | H4: 176.3905 | I4: 0
A5: 2019-20$ | B5: 1612.0491 | C5: 92.481732 | D5: 0.01407 | E5: 0 | F5: 1048.2721 | G5: 27.520913 | H5: 0 | I5: 0
A6: Apr-19 | B6: 1612.0491 | C6: 92.481732 | D6: 0.01407 | E6: 0 | F6: 1048.2721 | G6: 27.520913 | H6: 0 | I6: 0
A7: $ indicates as on April 30,2019
A8: Source: MSEI

Sheet 51
A1: Table 51: Trading Statistics of Interest Rate Futures at BSE, NSE and MSEI
A2: Year/ Month | B2: No. of Trading Days | C2: BSE | G2: NSE | K2: MSEI
C3: Interest Rate Futures | E3: Open Interest at the end of | G3: Interest Rate Futures | I3: Open Interest at the end of | K3: Interest RateFutures | M3: Open Interest at the end of
C4: No. of Contracts | D4: Traded Value (` crore) | E4: No. of Contracts | F4: Traded Value (` crore) | G4: No. of Contracts | H4: Traded Value (` crore) | I4: No. of Contracts | J4: Value (` crore) | K4: No. of Contracts | L4: Traded Value (` crore) | M4: No. of Contracts | N4: Value (` crore)
A5: 2018-19 | B5: 243 | C5: 5901468 | D5: 111222.29 | E5: 60205 | F5: 1214.2243 | G5: 12764150 | H5: 245407.18 | I5: 103589 | J5: 2054.4424 | K5: 0 | L5: 0 | M5: 0 | N5: 0
A6: 2019-20$ | B6: 18 | C6: 246140 | D6: 4738.1118 | E6: 66107 | F6: 1319.5983 | G6: 1232112 | H6: 24097.958 | I6: 122799 | J6: 2431.93 | K6: 0 | L6: 0 | M6: 0 | N6: 0
A7: Apr-19 | B7: 18 | C7: 246140 | D7: 4738.1118 | E7: 66107 | F7: 1319.5983 | G7: 1232112 | H7: 24097.958 | I7: 122799 | J7: 2431.93 | K7: 0 | L7: 0 | M7: 0 | N7: 0
A8: $ indicates as on April 30,2019
A9: Source: BSE, NSE and MSEI

Sheet 52
A1: Table 52: Settlement Statistics in Interest Rate Futures at BSE, NSE and MSEI (` crore)
A2: Year/ Month | B2: BSE | D2: NSE | F2: MSEI
B3: MTM Settlement | C3: Physical Delivery Settlement | D3: MTM Settlement | E3: Physical Delivery Settlement | F3: MTM Settlement | G3: Physical Delivery Settlement
A4: 2018-19 | B4: 308.58898 | C4: 13.792949 | D4: 634.57266 | E4: 13.227393 | F4: 0.0504 | G4: 0
A5: 2019-20$ | B5: 58.395731 | C5: 0.944379 | D5: 63.695625 | E5: 1.6079706 | F5: 0 | G5: 0
A6: Apr-19 | B6: 58.395731 | C6: 0.944379 | D6: 63.695625 | E6: 1.6079706 | F6: 0 | G6: 0
A7: $ indicates as on April 30,2019
A8: Source: NSE, BSE and MSEI

Sheet 53
A1: Table 53: Trends in Foreign Portfolio Investment
A2: Year/Month | B2: Gross Purchase (` crore) | C2: Gross Sales (` crores) | D2: Net Investment (` crores) | E2: Net Investment (US' $ mn.) | F2: Cumulative Net Investment (US $ mn.)
A3: 2018-19 | B3: 1640809.7 | C3: 1679740.8 | D3: -38931.12 | E3: -5498.74 | F3: 248154.18
A4: 2019-20$ | B4: 135799.91 | C4: 119072.05 | D4: 16727.86 | E4: 2406.9 | F4: 250561.08
A5: Apr-19 | B5: 135799.91 | C5: 119072.05 | D5: 16727.86 | E5: 2406.9 | F5: 250561.08
A6: $ indicates as on April 30,2019
A7: Source: NSDL, CDSL

Sheet 54
A1: Table 54: Notional Value of Offshore Derivative Instruments (ODIs) compared to Assets Under Custody (AUC) of FPIs/Deemed FPIs (` crore)
