Workbook

Sheet Data Summary
A1: Bulletin Reports Summary for Feb-19
A2: Report Name | B2: Data Status
A3: Table 1: SEBI Registered Market Intermediaries/Institutions | B3: Data Available
A4: Table 2: Company-Wise Capital Raised through Public and Rights Issues (Equity) | B4: Data Available
A5: Table 3: Open Offers under SEBI Takeover Code closed | B5: Data Available
A6: Table 4: Substantial Acquisition of Shares and Takeovers | B6: Data Available
A7: Table 5: Capital Raised from the Primary Market through though Public and Rights Issues | B7: Data Available
A8: Table 6: Issues Listed on SME Platform | B8: Data Available
A9: Table 7: Industry-wise Classification of Capital Raised through Public and Rights Issues | B9: Data Available
A10: Table 8: Sector-wise and Region-wise Distribution of Capital Mobilised through Public and Rights Issues | B10: Data Available
A11: Table 9: Size-wise Classification of Capital Raised through Public and Rights Issues | B11: Data Available
A12: Table 10: Capital Raised by Listed Companies from the Primary Market through QIPs | B12: Data Available
A13: Table 11: Preferential Allotments Listed at BSE and NSE | B13: Data Available
... A78: Table 76: Macro Economic Indicators | B78: Data Available

Sheet 1
A1: Table 1: SEBI Registered Market Intermediaries/Institutions
A2: Market Intermediaries / Institutions | B2: 2017-18 | C2: 2018-19$
A3: Stock Exchanges (Cash Segment) | B3: 5 | C3: 5
A4: Stock Exchanges (Equity Derivatives Segment) | B4: 3 | C4: 3
A5: Stock Exchanges (Currency Derivatives Segment) | B5: 3 | C5: 3
A6: Stock Exchanges (Commodity Derivatives Segment) | B6: 6 | C6: 5
A7: Brokers (Cash Segment) | B7: 3038 | C7: 2549
A8: Brokers (Equity Derivatives Segment) | B8: 2549 | C8: 2502
A9: Brokers (Currency Derivatives Segment) | B9: 2245 | C9: 2162
A10: Brokers (Debt Segment) | B10: 162 | C10: 179
A11: Brokers (Commodity Derivatives Segment) | B11: 1200 | C11: 1670
A12: Corporate Brokers(Cash Segment) | B12: 2647 | C12: 2223
A13: Foreign Portfolio Investors (FPIs) | B13: 9227 | C13: 9410
A14: Custodians | B14: 19 | C14: 20
... A36: STP Service Providers | B36: 2 | C36: 2
A38: $ indicates as on February 28,2019
A39: Source: SEBI, NSDL.

Sheet 2
A1: Table 2: Company-Wise Capital Raised through Public and Rights Issues (Equity)
A2: Sl.No. | B2: Name of the Issuer/Company | C2: Date of Opening | D2: Type of Issue | E2: Type of Instrument | F2: No. of Shares Issued | G2: Face Value (`) | H2: Premium Value (`) | I2: Issue Price (`) | J2: Size of Issue (` Crore)
A3: 1 | B3: Anmol India Limited | C3: 43510 | D3: SME-IPO | E3: Equity | F3: 3100000 | G3: 10 | H3: 23 | I3: 33 | J3: 10.23
A4: 2 | B4: Jonjua Overseas Limited | C4: 43511 | D4: SME-IPO | E4: Equity | F4: 1300000 | G4: 10 | H4: 0 | I4: 10 | J4: 1.3
A5: 3 | B5: Kranti Industries Limited | C5: 43516 | D5: SME-IPO | E5: Equity | F5: 2319000 | G5: 10 | H5: 27 | I5: 37 | J5: 8.5803
A6: 4 | B6: LGB FORGE LIMITED | C6: 43516 | D6: Rights | E6: Equity | F6: 88200912 | G6: 1 | H6: 2 | I6: 3 | J6: 26.46
A7: 5 | B7: Mindpool Technologies Limited | C7: 43516 | D7: SME-IPO | E7: Equity | F7: 1200000 | G7: 10 | H7: 20 | I7: 30 | J7: 3.6
A8: 6 | B8: Gleam Fabmat Limited | C8: 43518 | D8: SME-IPO | E8: Equity | F8: 3120000 | G8: 10 | H8: 0 | I8: 10 | J8: 3.12
A9: All the issues are compiled from the Prospectus of Issuer Companies filed with SEBI.
A10: Source: SEBI.

Sheet 3
A1: Table 3: Open Offers under SEBI Takeover Code closed during Feb-19
A2: Sl.No | B2: Target Company | C2: Acquirer | D2: Offer Opening Date | E2: Offer Closing Date | F2: Offer Size | H2: Offer Price (`) per share | I2: Offer Size (` Crore)
F3: No. of Shares | G3: Percent of Equity Capital
A4: 1 | B4: SHREE DIGVIJAY CEMENT COMPANY LIMITED | C4: NORTH FUND VI LLP | D4: 43487 | E4: 43500 | F4: 35611817 | G4: 25.1 | H4: 23.33 | I4: 83.08
A5: 2 | B5: HATHWAY CABLE AND DATACOM LIMITED | C5: JIO CONTENT DISTRIBUTION HOLDINGS PVT LTD, JIO INTERNET DISTRIBUTION HOLDINGS PVT. LTD., JIO CABLE A | D5: 43496 | E5: 43509 | F5: 460227170 | G5: 26 | H5: 32.35 | I5: 1488.83
A6: 3 | B6: TOURISM FINANCE CORPORATION OF INDIA LIMITED | C6: REDKITE CAPITAL PRIVATE LIMITED | D6: 43501 | E6: 43514 | F6: 20986355 | G6: 26 | H6: 157.2 | I6: 329.91
A7: 4 | B7: DEN NETWORKS LIMITED | C7: JIO FUTURISTIC DIGITAL HOLDINGS PVT LTD, JIO DIDGITAL DISTRIBUTION HOLDINGS PVT. LTD., JIO TELEVISIO | D7: 43504 | E7: 43518 | F7: 122183457 | G7: 25.58 | H7: 72.66 | I7: 887.78
A8: 5 | B8: GTPL HATHWAY LIMITED | C8: JIO CONTENT DISTRIBUTION HOLDINGS PVT LTD, JIO INTERNET DISTRIBUTION HOLDINGS PVT. LTD., JIO CABLE A | D8: 43504 | E8: 43518 | F8: 28840891 | G8: 25.64 | H8: 82.65 | I8: 238.37
A9: Source: SEBI.

Sheet 4
A1: Table 4: Substantial Acquisition of Shares and Takeovers
A2: Year / Month | B2: Open Offers
B3: Objectives | H3: Total
B4: Change in Control of Management | D4: Consolidation of Holdings | F4: Substantial Acquisition | H4: No. of Offers | I4: Amount (` crore)
B5: No. of Offers | C5: Amount (` crore) | D5: No. of Offers | E5: Amount (` crore) | F5: No. of Offers | G5: Amount (` crore)
A6: 2017-18 | B6: 43 | C6: 1510.12 | D6: 3 | E6: 38.27 | F6: 4 | G6: 220.93 | H6: 50 | I6: 1769.22
A7: 2018-19$ | B7: 62 | C7: 22969.03 | D7: 4 | E7: 4636.33 | F7: 4 | G7: 941.23 | H7: 70 | I7: 28546.59
A8: Apr-18 | B8: 13 | C8: 872.94 | D8: 1 | E8: 7.09 | F8: 1 | G8: 934.56 | H8: 15 | I8: 1814.59
A9: May-18 | B9: 7 | C9: 460.71 | D9: 0 | E9: 0 | F9: 1 | G9: 2.78 | H9: 8 | I9: 463.49
A10: Jun-18 | B10: 7 | C10: 32.41 | D10: 2 | E10: 927.24 | F10: 0 | G10: 0 | H10: 9 | I10: 959.65
A11: Jul-18 | B11: 6 | C11: 12.2 | D11: 1 | E11: 3702 | F11: 0 | G11: 0 | H11: 7 | I11: 3714.2
A12: Aug-18 | B12: 0 | C12: 0 | D12: 0 | E12: 0 | F12: 1 | G12: 2.23 | H12: 1 | I12: 2.23
A13: Sep-18 | B13: 3 | C13: 1318.86 | D13: 0 | E13: 0 | F13: 0 | G13: 0 | H13: 3 | I13: 1318.86
A14: Oct-18 | B14: 2 | C14: 70.56 | D14: 0 | E14: 0 | F14: 0 | G14: 0 | H14: 2 | I14: 70.56
A15: Nov-18 | B15: 4 | C15: 651.03 | D15: 0 | E15: 0 | F15: 0 | G15: 0 | H15: 4 | I15: 651.03
A16: Dec-18 | B16: 9 | C16: 43.41 | D16: 0 | E16: 0 | F16: 0 | G16: 0 | H16: 9 | I16: 43.41
A17: Jan-19 | B17: 6 | C17: 16478.94 | D17: 0 | E17: 0 | F17: 1 | G17: 1.66 | H17: 7 | I17: 16480.6
A18: Feb-19 | B18: 5 | C18: 3027.97 | D18: 0 | E18: 0 | F18: 0 | G18: 0 | H18: 5 | I18: 3027.97
A19: $ indicates as on February 28,2019
A20: Source: SEBI.

Sheet 5
A1: Table 5: Capital Raised from the Primary Market through though Public and Rights Issues
A2: Year / Month | B2: Total | D2: Category-Wise | H2: Issue-Type | L2: Instrument-Wise
D3: Public | F3: Rights | H3: Listed | J3: IPOs | L3: Equities | P3: CCPS/FCDs* | R3: Debt
L4: At Par | N4: At Premium
B5: No. of issues | C5: Amount (` crore) | D5: No. of issues | E5: Amount (` crore) | F5: No. of issues | G5: Amount (` crore) | H5: No. of issues | I5: Amount (` crore) | J5: No. of issues | K5: Amount (` crore) | L5: No. of issues | M5: Amount (` crore) | N5: No. of issues | O5: Amount (` crore) | P5: No. of issues | Q5: Amount (` crore) | R5: No. of issues | S5: Amount (` crore)
A6: 2017-18 | B6: 229 | C6: 110359.69 | D6: 208 | E6: 88959.63 | F6: 21 | G6: 21400.06 | H6: 30 | I6: 26585.22 | J6: 199 | K6: 83774.47 | L6: 3 | M6: 10.93 | N6: 218 | O6: 105176.2 | P6: 0 | Q6: 0 | R6: 8 | S6: 5172.56
A7: 2018-19$ | B7: =SUM(B8:B18) -> 144 | C7: =SUM(C8:C18) -> 51182.459 | D7: =SUM(D8:D18) -> 135 | E7: =SUM(E8:E18) -> 49058.627 | F7: =SUM(F8:F18) -> 9 | G7: =SUM(G8:G18) -> 2123.8319 | H7: =SUM(H8:H18) -> 30 | I7: =SUM(I8:I18) -> 35432.329 | ... S7: =SUM(S8:S18) -> 33308.5
A8: Apr-18 | B8: 16 | C8: 3555.31 | D8: 14 | E8: 3405.65 | F8: 2 | G8: 149.66 | H8: 4 | I8: 3363.9267 | J8: 12 | K8: 191.38 | L8: 1 | M8: 3.2 | N8: 13 | O8: 337.84 | P8: 0 | Q8: 0 | R8: 2 | S8: 3214.27
A9: May-18 | B9: 23 | C9: 14429.485 | D9: 23 | E9: 14429.485 | F9: 0 | G9: 0 | H9: 3 | I9: 12204.6 | J9: 20 | K9: 2224.8854 | L9: 0 | M9: 0 | N9: 20 | O9: 2224.8854 | P9: 0 | Q9: 0 | R9: 3 | S9: 12204.6
A10: Jun-18 | B10: 11 | C10: 3151.7067 | D10: 11 | E10: 3151.7067 | F10: 0 | G10: 0 | H10: 0 | I10: 0 | J10: 11 | K10: 3151.7067 | L10: 0 | M10: 0 | N10: 11 | O10: 3151.7067 | P10: 0 | Q10: 0 | R10: 0 | S10: 0
A11: Jul-18 | B11: 15 | C11: 10686.131 | D11: 13 | E11: 9708.3993 | F11: 2 | G11: 977.73191 | H11: 4 | I11: 6607.2519 | J11: 11 | K11: 4078.8793 | L11: 0 | M11: 0 | N11: 13 | O11: 5056.6112 | P11: 0 | Q11: 0 | R11: 2 | S11: 5629.52
A12: Aug-18 | B12: 11 | C12: 1254.11 | D12: 11 | E12: 1254.11 | F12: 0 | G12: 0 | H12: 0 | I12: 0 | J12: 11 | K12: 1254.11 | L12: 1 | M12: 1.35 | N12: 10 | O12: 1252.76 | P12: 0 | Q12: 0 | R12: 0 | S12: 0
A13: Sep-18 | B13: 20 | C13: 8700.7681 | D13: 20 | E13: 8700.7681 | F13: 0 | G13: 0 | H13: 4 | I13: 6284.51 | J13: 16 | K13: 2416.2581 | L13: 0 | M13: 0 | N13: 16 | O13: 2416.26 | P13: 0 | Q13: 0 | R13: 4 | S13: 6284.51
A14: Oct-18 | B14: 17 | C14: 1232.228 | D14: 17 | E14: 1232.228 | F14: 0 | G14: 0 | H14: 2 | I14: 706.79 | J14: 15 | K14: 525.438 | L14: 0 | M14: 0 | N14: 15 | O14: 525.44 | P14: 0 | Q14: 0 | R14: 2 | S14: 706.79
A15: Nov-18 | B15: 6 | C15: 317.52 | D15: 6 | E15: 317.52 | F15: 0 | G15: 0 | H15: 1 | I15: 262.02 | J15: 5 | K15: 55.5 | L15: 0 | M15: 0 | N15: 5 | O15: 55.5 | P15: 0 | Q15: 0 | R15: 1 | S15: 262.02
A16: Dec-18 | B16: 5 | C16: 1028.27 | D16: 3 | E16: 313.02 | F16: 2 | G16: 715.25 | H16: 3 | I16: 978.86 | J16: 2 | K16: 49.41 | L16: 0 | M16: 0 | N16: 4 | O16: 764.66 | P16: 0 | Q16: 0 | R16: 1 | S16: 263.61
A17: Jan-19 | B17: 12 | C17: 5485.17 | D17: 10 | E17: 5230.44 | F17: 2 | G17: 254.73 | H17: 6 | I17: 3709.44 | J17: 6 | K17: 1775.73 | L17: 1 | M17: 5.99 | N17: 7 | O17: 2024.47 | P17: 0 | Q17: 0 | R17: 4 | S17: 3454.71
A18: Feb-19 | B18: 8 | C18: 1341.76 | D18: 7 | E18: 1315.3 | F18: 1 | G18: 26.46 | H18: 3 | I18: 1314.93 | J18: 5 | K18: 26.83 | L18: 2 | M18: 4.45 | N18: 4 | O18: 48.84 | P18: 0 | Q18: 0 | R18: 2 | S18: 1288.47
A19: 1. The total provides category-wise total of any of the three sub-categories viz. public plus rights or issuer-type(listed plus IPOs) or instrument-wise(equities plus CCPS/FCDs plus debt). 2. Amount for public debt issue for last two months is provisional and may get updated 3. All the Issues are compiled from the Prospectus. of Issuer Companies filed with SEBI. 4. * CCPS: Compulsory Convertible Preference Shares, FCDs: Fully Convertible Debentures.
A20: 5. Equity public issues also includes issues listed on SME platform.
A21: $ indicates as on February 28,2019
A22: 6. Since April 2018, both the equity and debt issues are categorised based on their respective closing dates. Prior to April 2018, the equity issues were classified based on opening date of the issue, while debt issues were classfied based on closing date of the issue.
A23: Source: SEBI.

Sheet 6
A1: Table 6: Issues Listed on SME Platform
A2: Year/ Month | B2: Total
B3: No. of issue | C3: Amount (`crore)
A4: 2017-18 | B4: 156 | C4: 2360.8709
A5: 2018-19$ | B5: 102 | C5: 1718.5372
A6: Apr-18 | B6: 12 | C6: 191.3762
A7: May-18 | B7: 19 | C7: 380.88536
A8: Jun-18 | B8: 8 | C8: 135.5554
A9: Jul-18 | B9: 9 | C9: 153.42314
A10: Aug-18 | B10: 10 | C10: 122.9223
A11: Sep-18 | B11: 14 | C11: 309.23812
A12: Oct-18 | B12: 14 | C12: 181.848
A13: Nov-18 | B13: 5 | C13: 55.5004
A14: Dec-18 | B14: 2 | C14: 49.41
A15: Jan-19 | B15: 4 | C15: 111.548
A16: Feb-19 | B16: 5 | C16: 26.8303
A17: $ indicates as on February 28,2019
A18: Source: SEBI

Sheet 7
A1: Table 7: Industry-wise Classification of Capital Raised through Public and Rights Issues
A2: Industry | B2: 2018-19$ | D2: Feb-19
B3: No. of issues | C3: Amount (`crore) | D3: No. of issues | E3: Amount (` crore)
A4: Airlines | B4: 0 | C4: 0 | D4: 0 | E4: 0
A5: Automobiles | B5: 1 | C5: 8.58 | D5: 1 | E5: 8.58
A6: Banks/FIs | B6: 1 | C6: 1131.1876 | D6: 0 | E6: 0
A7: Cement/ Constructions | B7: 4 | C7: 542.1929 | D7: 0 | E7: 0
A8: Chemical | B8: 4 | C8: 621.73783 | D8: 0 | E8: 0
A9: Consumer Services | B9: 1 | C9: 18.7452 | D9: 0 | E9: 0
A10: Electronic Equipments/ Products | B10: 7 | C10: 259.00511 | D10: 0 | E10: 0
A11: Engineering | B11: 9 | C11: 466.7348 | D11: 0 | E11: 0
A12: Entertainment | B12: 1 | C12: 1.35 | D12: 0 | E12: 0
A13: Finance | B13: 26 | C13: 37584.767 | D13: 2 | E13: 1288.47
A14: Food processing | B14: 4 | C14: 90.42232 | D14: 0 | E14: 0
A15: Healthcare | B15: 3 | C15: 58.3014 | D15: 0 | E15: 0
... A27: Total | B27: 145 | C27: 51719.546 | D27: 8 | E27: 1341.76
A28: $ indicates as on February 28,2019
A29: Source: SEBI.

Sheet 8
A1: Table 8: Sector-wise and Region-wise Distribution of Capital Mobilised through Public and Rights Issues
A2: Year / Month | B2: Total | D2: Sector-wise | H2: Region-wise
D3: Private | F3: Public | H3: Northern | J3: Eastern | L3: Western | N3: Southern | P3: Central | R3: Foreign
B4: No. of Issue | C4: Amount (`Crores) | D4: No. of Issue | E4: Amount (` Crores) | F4: No. of Issue | G4: Amount (` Crores) | H4: No. of Issue | I4: Amount (` Crores) | J4: No. of Issue | K4: Amount (` Crores) | L4: No. of Issue | M4: Amount (` Crores) | N4: No. of Issue | O4: Amount (` Crores) | P4: No. of Issue | Q4: Amount (` Crores) | R4: No. of Issue | S4: Amount (` Crores)
A5: 2017-18 | B5: 229 | C5: 110359.69 | D5: 222 | E5: 74118.09 | F5: 7 | G5: 36241.6 | H5: 62 | I5: 13118.88 | J5: 9 | K5: 6628.89 | L5: 129 | M5: 76310.38 | N5: 29 | O5: 14301.53 | P5: 0 | Q5: 0 | R5: 0 | S5: 0
A6: 2018-19$ | B6: 144 | C6: 51182.352 | D6: 141 | E6: 49911.552 | F6: 3 | G6: 1270.8 | H6: 27 | I6: 5342.7705 | J6: 9 | K6: 1165.4395 | L6: 85 | M6: 33603.344 | N6: 19 | O6: 10955.107 | P6: 4 | Q6: 115.7 | R6: 0 | S6: 0
A7: Apr-18 | B7: 16 | C7: 3555.2982 | D7: 16 | E7: 3555.2982 | F7: 0 | G7: 0 | H7: 4 | I7: 90.19618 | J7: 0 | K7: 0 | L7: 8 | M7: 149.12471 | N7: 3 | O7: 3231.382 | P7: 1 | Q7: 84.6 | R7: 0 | S7: 0
A8: May-18 | B8: 23 | C8: 14429.485 | D8: 23 | E8: 14429.485 | F8: 0 | G8: 0 | H8: 4 | I8: 154.6 | J8: 1 | K8: 509.81 | L8: 16 | M8: 13745.875 | N8: 0 | O8: 0 | P8: 2 | Q8: 19.2 | R8: 0 | S8: 0
A9: Jun-18 | B9: 11 | C9: 3151.7067 | D9: 10 | E9: 2691.1967 | F9: 1 | G9: 460.51 | H9: 1 | I9: 460.51 | J9: 0 | K9: 0 | L9: 9 | M9: 2679.2967 | N9: 0 | O9: 0 | P9: 1 | Q9: 11.9 | R9: 0 | S9: 0
A10: Jul-18 | B10: 15 | C10: 10686.03 | D10: 15 | E10: 10686.03 | F10: 0 | G10: 0 | H10: 4 | I10: 1598.2768 | J10: 1 | K10: 60.0075 | L10: 8 | M10: 4851.3931 | N10: 2 | O10: 4176.3538 | P10: 0 | Q10: 0 | R10: 0 | S10: 0
A11: Aug-18 | B11: 11 | C11: 1254.11 | D11: 11 | E11: 1254.11 | F11: 0 | G11: 0 | H11: 2 | I11: 29.8 | J11: 0 | K11: 0 | L11: 8 | M11: 93.12 | N11: 1 | O11: 1131.19 | P11: 0 | Q11: 0 | R11: 0 | S11: 0
A12: Sep-18 | B12: 20 | C12: 8700.7719 | D12: 19 | E12: 8234.0719 | F12: 1 | G12: 466.7 | H12: 4 | I12: 2476.49 | J12: 0 | K12: 0 | L12: 13 | M12: 5262.0945 | N12: 3 | O12: 962.19 | P12: 0 | Q12: 0 | R12: 0 | S12: 0
A13: Oct-18 | B13: 17 | C13: 1232.23 | D13: 16 | E13: 888.64 | F13: 1 | G13: 343.59 | H13: 2 | I13: 7.896 | J13: 4 | K13: 387.072 | L13: 8 | M13: 110.4792 | N13: 3 | O13: 726.7808 | P13: 0 | Q13: 0 | R13: 0 | S13: 0
A14: Nov-18 | B14: 6 | C14: 317.52 | D14: 6 | E14: 317.52 | F14: 0 | G14: 0 | H14: 0 | I14: 0 | J14: 1 | K14: 13.32 | L14: 3 | M14: 10.68 | N14: 2 | O14: 293.52 | P14: 0 | Q14: 0 | R14: 0 | S14: 0
A15: Dec-18 | B15: 5 | C15: 1028.27 | D15: 5 | E15: 1028.27 | F15: 0 | G15: 0 | H15: 1 | I15: 217.67149 | J15: 0 | K15: 0 | L15: 3 | M15: 768.48 | N15: 1 | O15: 42.12 | P15: 0 | Q15: 0 | R15: 0 | S15: 0
A16: Jan-19 | B16: 12 | C16: 5485.17 | D16: 12 | E16: 5485.17 | F16: 0 | G16: 0 | H16: 3 | I16: 302.91 | J16: 1 | K16: 185 | L16: 6 | M16: 4762.05 | N16: 2 | O16: 235.21 | P16: 0 | Q16: 0 | R16: 0 | S16: 0
A17: Feb-19 | B17: 8 | C17: 1341.76 | D17: 8 | E17: 1341.76 | F17: 0 | G17: 0 | H17: 2 | I17: 4.42 | J17: 1 | K17: 10.23 | L17: 3 | M17: 1170.75 | N17: 2 | O17: 156.36 | P17: 0 | Q17: 0 | R17: 0 | S17: 0
A18: $ indicates as on February 28,2019
A19: Source: SEBI.

Sheet 9
A1: Table 9: Size-wise Classification of Capital Raised through Public and Rights Issues
A2: Year / Month | B2: Total | D2: < 5 crore | F2: ≥ 5crore - < 10crore | H2: ≥ 10 crore - < 50 crore | J2: ≥ 50 crore - < 100 crore | L2: ≥ 100 crore
B3: No. of issue | C3: Amount (` crore) | D3: No. of issue | E3: Amount (` crore) | F3: No. of issue | G3: Amount (` crore) | H3: No. of issue | I3: Amount (` crore) | J3: No. of issue | K3: Amount (` crore) | L3: No. of issue | M3: Amount (` crore)
A4: 2017-18 | B4: 229 | C4: 110359.31 | D4: 28 | E4: 108.28 | F4: 41 | G4: 273.58 | H4: 90 | I4: 1848 | J4: 9 | K4: 615.59 | L4: 61 | M4: 107513.86
A5: 2018-19$ | B5: =SUM(B6:B16) -> 144 | C5: =SUM(C6:C16) -> 51182.359 | D5: =SUM(D6:D16) -> 18 | E5: =SUM(E6:E16) -> 62.6668 | F5: =SUM(F6:F16) -> 27 | G5: =SUM(G6:G16) -> 197.3294 | H5: =SUM(H6:H16) -> 56 | I5: =SUM(I6:I16) -> 1226.141 | ... M5: =SUM(M6:M16) -> 49258.706
A6: Apr-18 | B6: 16 | C6: 3555.3 | D6: 3 | E6: 11.9 | F6: 4 | G6: 24.23 | H6: 5 | I6: 120.38 | J6: 2 | K6: 184.52 | L6: 2 | M6: 3214.27
A7: May-18 | B7: 23 | C7: 14429.485 | D7: 1 | E7: 4.44 | F7: 8 | G7: 64.674 | H7: 9 | I7: 233.86136 | J7: 1 | K7: 77.91 | L7: 4 | M7: 14048.6
A8: Jun-18 | B8: 11 | C8: 3151.7054 | D8: 0 | E8: 0 | F8: 2 | G8: 14.164 | H8: 6 | I8: 121.3914 | J8: 0 | K8: 0 | L8: 3 | M8: 3016.15
A9: Jul-18 | B9: 15 | C9: 10686.031 | D9: 1 | E9: 4.5084 | F9: 3 | G9: 22.4534 | H9: 4 | I9: 66.45384 | J9: 1 | K9: 60.0075 | L9: 6 | M9: 10532.608
A10: Aug-18 | B10: 11 | C10: 1254.12 | D10: 2 | E10: 6.13 | F10: 2 | G10: 15.67 | H10: 6 | I10: 101.13 | J10: 0 | K10: 0 | L10: 1 | M10: 1131.19
A11: Sep-18 | B11: 20 | C11: 8700.7681 | D11: 3 | E11: 10.7184 | F11: 2 | G11: 14.268 | H11: 7 | I11: 169.174 | J11: 2 | K11: 115.07772 | L11: 6 | M11: 8391.53
A12: Oct-18 | B12: 17 | C12: 1232.2304 | D12: 3 | E12: 12.78 | F12: 2 | G12: 13.5 | H12: 9 | I12: 155.5704 | J12: 0 | K12: 0 | L12: 3 | M12: 1050.38
A13: Nov-18 | B13: 6 | C13: 317.52 | D13: 2 | E13: 4.17 | F13: 1 | G13: 6.51 | H13: 2 | I13: 44.82 | J13: 0 | K13: 0 | L13: 1 | M13: 262.02
A14: Dec-18 | B14: 5 | C14: 1028.2683 | D14: 0 | E14: 0 | F14: 1 | G14: 7.29 | H14: 1 | I14: 42.12 | J14: 0 | K14: 0 | L14: 3 | M14: 978.85832
A15: Jan-19 | B15: 12 | C15: 5485.17 | D15: 0 | E15: 0 | F15: 1 | G15: 5.99 | H15: 5 | I15: 134.55 | J15: 0 | K15: 0 | L15: 6 | M15: 5344.63
A16: Feb-19 | B16: 8 | C16: 1341.76 | D16: 3 | E16: 8.02 | F16: 1 | G16: 8.58 | H16: 2 | I16: 36.69 | J16: 0 | K16: 0 | L16: 2 | M16: 1288.47
A17: $ indicates as on February 28,2019
A18: Source: SEBI.

Sheet 10
A1: Table 10: Capital Raised by Listed Companies from the Primary Market through QIPs
A2: Year / Month | B2: Only BSE | D2: Only NSE | F2: Only MSEI | H2: Both NSE and BSE | J2: Total
B3: No. of issues | C3: Amount (` Crores) | D3: No. of issues | E3: Amount (` Crores) | F3: No. of issues | G3: Amount (` Crores) | H3: No. of issues | I3: Amount (` Crores) | J3: No. of issues | K3: Amount (` Crores)
A4: 2017-18 | B4: 0 | C4: 0 | D4: 0 | E4: 0 | F4: 0 | G4: 0 | H4: 53 | I4: 67238 | J4: 53 | K4: 67238
A5: 2018-19$ | B5: 0 | C5: 0 | D5: 0 | E5: 0 | F5: 0 | G5: 0 | H5: 12 | I5: 7468.7314 | J5: 12 | K5: 7468.7314
A6: Apr-18 | B6: 0 | C6: 0 | D6: 0 | E6: 0 | F6: 0 | G6: 0 | H6: 3 | I6: 1862 | J6: 3 | K6: 1862
A7: May-18 | B7: 0 | C7: 0 | D7: 0 | E7: 0 | F7: 0 | G7: 0 | H7: 5 | I7: 1008 | J7: 5 | K7: 1008
A8: Jun-18 | B8: 0 | C8: 0 | D8: 0 | E8: 0 | F8: 0 | G8: 0 | H8: 1 | I8: 1200 | J8: 1 | K8: 1200
A9: Jul-18 | B9: 0 | C9: 0 | D9: 0 | E9: 0 | F9: 0 | G9: 0 | H9: 0 | I9: 0 | J9: 0 | K9: 0
A10: Aug-18 | B10: 0 | C10: 0 | D10: 0 | E10: 0 | F10: 0 | G10: 0 | H10: 2 | I10: 2888 | J10: 2 | K10: 2888
A11: Sep-18 | B11: 0 | C11: 0 | D11: 0 | E11: 0 | F11: 0 | G11: 0 | H11: 0 | I11: 0 | J11: 0 | K11: 0
A12: Oct-18 | B12: 0 | C12: 0 | D12: 0 | E12: 0 | F12: 0 | G12: 0 | H12: 0 | I12: 0 | J12: 0 | K12: 0
A13: Nov-18 | B13: 0 | C13: 0 | D13: 0 | E13: 0 | F13: 0 | G13: 0 | H13: 0 | I13: 0 | J13: 0 | K13: 0
A14: Dec-18 | B14: 0 | C14: 0 | D14: 0 | E14: 0 | F14: 0 | G14: 0 | H14: 0 | I14: 0 | J14: 0 | K14: 0
A15: Jan-19 | B15: 0 | C15: 0 | D15: 0 | E15: 0 | F15: 0 | G15: 0 | H15: 1 | I15: 510.79 | J15: 1 | K15: 510.79
A16: Feb-19 | B16: 0 | C16: 0 | D16: 0 | E16: 0 | F16: 0 | G16: 0 | H16: 0 | I16: 0 | J16: 0 | K16: 0
A17: 1. The above data includes both "no. of issues" and "Amount" raised on conversion of convertible securities issued on QIP basis. 2. 2017-18, Includes one issue of Institutional Placement Programme (Issue Size of Rs. 873.92 crore).
A18: $ indicates as on February 28,2019
A19: Source: BSE, NSE and MSEI.

Sheet 11
A1: Table 11: Preferential Allotments Listed at BSE and NSE
A2: Year/Month | B2: Only BSE | D2: Only NSE | F2: Only MSEI | H2: Both NSE and BSE | J2: Total
B3: No. of issues | C3: Amount (` Crores) | D3: No. of issues | E3: Amount (` Crores) | F3: No. of issues | G3: Amount (`Crores) | H3: No. of issues | I3: Amount ` Crores) | J3: No. of issues | K3: Amount (`Crores)
A4: 2017-18 | B4: 189 | C4: 2563.36 | D4: 18 | E4: 715.867 | F4: 8 | G4: 27.73 | H4: 200 | I4: 56193.111 | J4: 407 | K4: 59472.648
A5: 2018-19$ | B5: 200 | C5: 10732.22 | D5: 19 | E5: 8030.59 | F5: 4 | G5: 23.59 | H5: 159 | I5: 164000.5 | J5: 382 | K5: 182786.9
A6: Apr-18 | B6: 17 | C6: 3359.53 | D6: 3 | E6: 1931.55 | F6: 1 | G6: 13.7 | H6: 39 | I6: 67145.29 | J6: 60 | K6: 72450.07
A7: May-18 | B7: 14 | C7: 2131.5 | D7: 1 | E7: 52.43 | F7: 0 | G7: 0 | H7: 10 | I7: 627.91 | J7: 25 | K7: 2811.84
A8: Jun-18 | B8: 23 | C8: 2906.38 | D8: 0 | E8: 0 | F8: 1 | G8: 2.64 | H8: 16 | I8: 21640.46 | J8: 40 | K8: 24549.48
A9: Jul-18 | B9: 30 | C9: 530.4 | D9: 4 | E9: 15 | F9: 0 | G9: 0 | H9: 14 | I9: 10815.83 | J9: 48 | K9: 11361.23
A10: Aug-18 | B10: 17 | C10: 386.8 | D10: 3 | E10: 3272.27 | F10: 0 | G10: 0 | H10: 14 | I10: 579.6 | J10: 34 | K10: 4238.67
A11: Sep-18 | B11: 15 | C11: 261.87 | D11: 2 | E11: 2710.08 | F11: 0 | G11: 0 | H11: 5 | I11: 440.22 | J11: 22 | K11: 3412.17
A12: Oct-18 | B12: 17 | C12: 140.82 | D12: 0 | E12: 0 | F12: 1 | G12: 1.94 | H12: 12 | I12: 3504.63 | J12: 30 | K12: 3647.39
A13: Nov-18 | B13: 14 | C13: 219.02 | D13: 3 | E13: 18.94 | F13: 0 | G13: 0 | H13: 17 | I13: 24021.51 | J13: 34 | K13: 24259.47
A14: Dec-18 | B14: 22 | C14: 425.95 | D14: 0 | E14: 0 | F14: 1 | G14: 5.31 | H14: 13 | I14: 2784.12 | J14: 36 | K14: 3215.38
A15: Jan-19 | B15: 15 | C15: 201.42 | D15: 1 | E15: 7.32 | F15: 0 | G15: 0 | H15: 10 | I15: 19635.74 | J15: 26 | K15: 19844.48
A16: Feb-19 | B16: 16 | C16: 168.53 | D16: 2 | E16: 23 | F16: 0 | G16: 0 | H16: 9 | I16: 12805.19 | J16: 27 | K16: 12996.72
A17: $ indicates as on February 28,2019
A18: Source: BSE, NSE and MSEI.

Sheet 12
A1: Table 12: Private Placement of Corporate Debt Reported to BSE and NSE
A2: Year/Month | B2: Only NSE | D2: Only BSE | F2: Both NSE and BSE | H2: TOTAL
B3: No. of Issues | C3: Amount (`Crores) | D3: No. of Issues | E3: Amount (` Crores) | F3: No. of Issues | G3: Amount (` Crores) | H3: No. of Issues | I3: Amount (` Crores)
A4: 2017-18 | B4: 721 | C4: 170834.77 | D4: 1812 | E4: 234614.24 | F4: 173 | G4: 193698 | H4: 2706 | I4: 599147.01
A5: 2018-19$ | B5: 436 | C5: 152699.99 | D5: 1543 | E5: 202371.48 | F5: 159 | G5: 140928.72 | H5: 2138 | I5: 465367.78
A6: Apr-18 | B6: 42 | C6: 18516.74 | D6: 214 | E6: 31435 | F6: 16 | G6: 16187 | H6: 272 | I6: 66138.74
A7: May-18 | B7: 15 | C7: 1924 | D7: 104 | E7: 7114.98 | F7: 3 | G7: 1500 | H7: 122 | I7: 10538.98
A8: Jun-18 | B8: 33 | C8: 11031.46 | D8: 92 | E8: 7838.36 | F8: 9 | G8: 4863.5 | H8: 134 | I8: 23733.32
A9: Jul-18 | B9: 48 | C9: 11555.75 | D9: 161 | E9: 19076.66 | F9: 12 | G9: 1319.4 | H9: 221 | I9: 1319.4
A10: Aug-18 | B10: 48 | C10: 11382.65 | D10: 159 | E10: 17721.12 | F10: 13 | G10: 7812.3 | H10: 220 | I10: 36916.07
A11: Sep-18 | B11: 45 | C11: 10823.91 | D11: 152 | E11: 19543.6 | F11: 7 | G11: 1434.2 | H11: 204 | I11: 31801.71
A12: Oct-18 | B12: 31 | C12: 11145.59 | D12: 116 | E12: 5589.39 | F12: 8 | G12: 15159 | H12: 155 | I12: 31893.98
A13: Nov-18 | B13: 34 | C13: 16814.55 | D13: 104 | E13: 18366.16 | F13: 20 | G13: 20034.1 | H13: 158 | I13: 55214.81
A14: Dec-18 | B14: 52 | C14: 28334.722 | D14: 109 | E14: 25663.85 | F14: 24 | G14: 30926.5 | H14: 185 | I14: 84925.072
A15: Jan-19 | B15: 59 | C15: 18057 | D15: 192 | E15: 33432.89 | F15: 33 | G15: 32097.328 | H15: 284 | I15: 83587.218
A16: Feb-19 | B16: 29 | C16: 13113.616 | D16: 140 | E16: 16589.472 | F16: 14 | G16: 9595.3945 | H16: 183 | I16: 39298.483
A17: $ indicates as on February 28, 2018
A18: Source: BSE and NSE

Sheet 13
A1: Table 13: Trading in the Corporate Debt Market
A2: Year / Month | B2: BSE | D2: NSE | F2: MSEI | H2: Total
B3: No. of Trades | C3: Traded Value (` crore) | D3: No. of Trades | E3: Traded Value (` crore) | F3: No. of Trades | G3: Traded Value (` crore) | H3: No. of Trades | I3: Traded Value (` crore)
A4: 2017-18 | B4: 30008 | C4: 494674.7 | D4: 61395 | E4: 1303423.4 | F4: 1 | G4: 0.22 | H4: 91404 | I4: 1798098.4 | J4: 152800
A5: 2018-19$ | B5: =SUM(B6:B16) -> 37952 | C5: =SUM(C6:C16) -> 552731.13 | D5: =SUM(D6:D16) -> 52248 | E5: =SUM(E6:E16) -> 992748.44 | F5: =SUM(F6:F16) -> 0 | G5: =SUM(G6:G16) -> 0 | H5: =SUM(H6:H16) -> 90200 | I5: =SUM(I6:J16) -> 1545479.6
A6: Apr-18 | B6: 3442 | C6: 48912.74 | D6: 5588 | E6: 113974.59 | F6: 0 | G6: 0 | H6: 9030 | I6: 162887.33
A7: May-18 | B7: 4470 | C7: 87009.74 | D7: 1770 | E7: 22494.35 | F7: 0 | G7: 0 | H7: 6240 | I7: 109504.09
A8: Jun-18 | B8: 3067 | C8: 53079.63 | D8: 5252 | E8: 103335.67 | F8: 0 | G8: 0 | H8: 8319 | I8: 156415.3
A9: Jul-18 | B9: 3122 | C9: 54314.01 | D9: 4535 | E9: 91539.73 | F9: 0 | G9: 0 | H9: 7657 | I9: 145853.74
A10: Aug-18 | B10: 3534 | C10: 43548.04 | D10: 5036 | E10: 92454.69 | F10: 0 | G10: 0 | H10: 8570 | I10: 136002.73
A11: Sep-18 | B11: 2840 | C11: 37394.78 | D11: 4388 | E11: 85624.29 | F11: 0 | G11: 0 | H11: 7228 | I11: 123019.07
A12: Oct-18 | B12: 2958 | C12: 35876.15 | D12: 4572 | E12: 85078.91 | F12: 0 | G12: 0 | H12: 7530 | I12: 120955.06
A13: Nov-18 | B13: 2921 | C13: 40772.97 | D13: 4214 | E13: 82928.38 | F13: 0 | G13: 0 | H13: 7135 | I13: 123701.35
A14: Dec-18 | B14: 3626 | C14: 56467.11 | D14: 5903 | E14: 123701.67 | F14: 0 | G14: 0 | H14: 9529 | I14: 180168.78
A15: Jan-19 | B15: 4416 | C15: 55223.13 | D15: 6164 | E15: 109125.49 | F15: 0 | G15: 0 | H15: 10580 | I15: 164348.62
A16: Feb-19 | B16: 3556 | C16: 40132.83 | D16: 4826 | E16: 82490.67 | F16: 0 | G16: 0 | H16: 8382 | I16: 122623.5
A17: $ indicates as on February 28, 2018
A18: Source: BSE, NSE and MSEI.

Sheet 14
A1: Table 14: Ratings Assigned for Long-term Corporate Debt Securities (Maturity ≥ 1 year)
A2: Grade | B2: Investment Grade | J2: Non-Investment Grade | L2: Total
B3: Highest Safety (AAA) | D3: High Safety (AA) | F3: Adequate Safety (A) | H3: Moderate Safety (BBB)
A4: Period | B4: No. of issue | C4: Amount (`crore) | D4: No. of issue | E4: Amount (` crore) | F4: No. of issue | G4: Amount (` crore) | H4: No. of issue | I4: Amount (` crore) | J4: No. of issue | K4: Amount (` crore) | L4: No. of issue | M4: Amount (` crore)
A5: 2017-18 | B5: 280 | C5: 1596761.1 | D5: 538 | E5: 408841.17 | F5: 322 | G5: 104834 | H5: 216 | I5: 16271.32 | J5: 88 | K5: 10928.98 | L5: 1444 | M5: 2137636.5
A6: 2018-19$ | B6: =SUM(B7:B17) -> 240 | C6: =SUM(C7:C17) -> 1270384.8 | D6: =SUM(D7:D17) -> 347 | E6: =SUM(E7:E17) -> 286488.45 | F6: =SUM(F7:F17) -> 306 | G6: =SUM(G7:G17) -> 93148.92 | H6: =SUM(H7:H17) -> 207 | I6: =SUM(I7:I17) -> 19156.626 | ... M6: =SUM(M7:M17) -> 1680617.4
A7: Apr-18 | B7: 21 | C7: 85560.55 | D7: 22 | E7: 16730 | F7: 13 | G7: 7273.57 | H7: 9 | I7: 1837.03 | J7: 3 | K7: 1496.41 | L7: 68 | M7: 112897.56
A8: May-18 | B8: 15 | C8: 89278.02 | D8: 22 | E8: 8175 | F8: 16 | G8: 3913.14 | H8: 11 | I8: 1455.11 | J8: 2 | K8: 151 | L8: 66 | M8: 102972.27
A9: Jun-18 | B9: 12 | C9: 35060.97 | D9: 32 | E9: 29036.61 | F9: 28 | G9: 8958.55 | H9: 15 | I9: 2349.19 | J9: 7 | K9: 664.43 | L9: 94 | M9: 76069.75
A10: Jul-18 | B10: 21 | C10: 74224.46 | D10: 29 | E10: 33412.13 | F10: 24 | G10: 3184.32 | H10: 14 | I10: 1432.026 | J10: 3 | K10: 42.76 | L10: 91 | M10: 112295.7
A11: Aug-18 | B11: 23 | C11: 150168.39 | D11: 41 | E11: 44267.69 | F11: 31 | G11: 5276.04 | H11: 18 | I11: 1549.69 | J11: 5 | K11: 4729.1 | L11: 118 | M11: 205990.91
A12: Sep-18 | B12: 19 | C12: 44744.61 | D12: 34 | E12: 16583.67 | F12: 25 | G12: 4558.79 | H12: 19 | I12: 1307.91 | J12: 3 | K12: 580 | L12: 100 | M12: 67774.98
A13: Oct-18 | B13: 24 | C13: 228957.98 | D13: 25 | E13: 32123.03 | F13: 14 | G13: 2177.16 | H13: 19 | I13: 492.77 | J13: 1 | K13: 28 | L13: 83 | M13: 263778.94
A14: Nov-18 | B14: 17 | C14: 34811.13 | D14: 44 | E14: 35696.02 | F14: 21 | G14: 7363.66 | H14: 18 | I14: 1231.1 | J14: 5 | K14: 225.66 | L14: 105 | M14: 79327.57
A15: Dec-18 | B15: 33 | C15: 201626.46 | D15: 34 | E15: 34743.62 | F15: 26 | G15: 5800.35 | H15: 20 | I15: 696.74 | J15: 4 | K15: 457 | L15: 117 | M15: 243324.17
A16: Jan-19 | B16: 26 | C16: 74616.84 | D16: 34 | E16: 18764.15 | F16: 80 | G16: 36700.69 | H16: 43 | I16: 6252.83 | J16: 10 | K16: 2694.2 | L16: 193 | M16: 139028.71
A17: Feb-19 | B17: 29 | C17: 251335.39 | D17: 30 | E17: 16956.53 | F17: 28 | G17: 7942.65 | H17: 21 | I17: 552.23 | J17: 3 | K17: 370 | L17: 111 | M17: 277156.8
A18: $ indicates as on February 28,2019
A19: Source: Credit Rating Agencies.

Sheet 15
A1: Table 15: Review of Accepted Ratings of Corporate Debt Securities (Maturity ≥ 1 year)
A2: Grade | B2: Upgraded | D2: Downgraded | F2: Reaffirmed | H2: Rating Watch | J2: Withdrawn/ Suspended | L2: Total
A3: Period | B3: No. of issue | C3: Amount (`crore) | D3: No. of issue | E3: Amount (`crore) | F3: No. of issue | G3: Amount (`crore) | H3: No. of issue | I3: Amount (`crore) | J3: No. of issue | K3: Amount (`crore) | L3: No. of issue | M3: Amount (`crore)
A4: 2017-18 | B4: 360 | C4: 154861.12 | D4: 331 | E4: 303486.87 | F4: 3591 | G4: 10772518 | H4: 134 | I4: 202450.83 | J4: 894 | K4: 249959.15 | L4: 5310 | M4: 11683276
A5: 2018-19$ | B5: =SUM(B6:B16) -> 650 | C5: =SUM(C6:C16) -> 245768.09 | D5: =SUM(D6:D16) -> 780 | E5: =SUM(E6:E16) -> 782291.3 | F5: =SUM(F6:F16) -> 4980 | G5: =SUM(G6:G16) -> 9999879.1 | H5: =SUM(H6:H16) -> 443 | I5: =SUM(I6:I16) -> 1070982.5 | ... M5: =SUM(M6:M16) -> 12526638
A6: Apr-18 | B6: 28 | C6: 19680.55 | D6: 7 | E6: 683.21 | F6: 310 | G6: 523390.07 | H6: 3 | I6: 2351 | J6: 66 | K6: 30074.17 | L6: 414 | M6: 576179
A7: May-18 | B7: 36 | C7: 8241.89 | D7: 65 | E7: 58224.05 | F7: 369 | G7: 629541.83 | H7: 11 | I7: 7050 | J7: 82 | K7: 16243.84 | L7: 563 | M7: 719301.61
A8: Jun-18 | B8: 122 | C8: 24678.66 | D8: 31 | E8: 27659.57 | F8: 604 | G8: 852387.89 | H8: 3 | I8: 7235 | J8: 101 | K8: 11516.43 | L8: 861 | M8: 923477.55
A9: Jul-18 | B9: 24 | C9: 3101.28 | D9: 52 | E9: 33374.91 | F9: 569 | G9: 694334.55 | H9: 22 | I9: 13707.45 | J9: 116 | K9: 45149.74 | L9: 783 | M9: 789667.93
A10: Aug-18 | B10: 155 | C10: 114544.94 | D10: 63 | E10: 39757.59 | F10: 520 | G10: 756647.31 | H10: 17 | I10: 17147 | J10: 115 | K10: 75942.13 | L10: 870 | M10: 1004039
A11: Sep-18 | B11: 49 | C11: 16439.61 | D11: 149 | E11: 116232.35 | F11: 606 | G11: 1585493.2 | H11: 59 | I11: 67280.51 | J11: 69 | K11: 7939.5 | L11: 932 | M11: 1793385.2
A12: Oct-18 | B12: 83 | C12: 46694.79 | D12: 38 | E12: 16351.23 | F12: 351 | G12: 1166733.7 | H12: 11 | I12: 4195.1 | J12: 59 | K12: 10214.71 | L12: 542 | M12: 1244189.6
A13: Nov-18 | B13: 15 | C13: 1348.16 | D13: 82 | E13: 129966.3 | F13: 451 | G13: 556977.9 | H13: 52 | I13: 54116.8 | J13: 86 | K13: 22903.27 | L13: 686 | M13: 765312.43
A14: Dec-18 | B14: 72 | C14: 5921.18 | D14: 52 | E14: 32465.97 | F14: 476 | G14: 1244178.2 | H14: 44 | I14: 739936 | J14: 85 | K14: 10848.29 | L14: 729 | M14: 2032349.6
A15: Jan-19 | B15: 33 | C15: 2350.75 | D15: 36 | E15: 47927.16 | F15: 309 | G15: 523632.84 | H15: 104 | I15: 79515 | J15: 73 | K15: 22677.48 | L15: 555 | M15: 676103.23
A16: Feb-19 | B16: 33 | C16: 2766.28 | D16: 205 | E16: 279648.96 | F16: 415 | G16: 1466561.6 | H16: 117 | I16: 78448.67 | J16: 84 | K16: 175207.16 | L16: 854 | M16: 2002632.6
A17: $ indicates as on February 28,2019
A18: Source: Credit Rating Agencies.

Sheet 16
A1: Table 16: Distribution of Turnover on Cash Segments of Stock Exchanges (`crore)
A2: Stock Exchanges | B2: 2017-18 | C2: 2018-19$ | D2: Feb-19
A3: BSE | B3: 1082968.2 | C3: 694613.02 | D3: 50655.69
A4: MSEI | B4: 192.76941 | C4: 24.514193 | D4: 5.2180822
A5: NSE | B5: 7234825.7 | C5: 7251779.8 | D5: 639270.41
A6: $ indicates as on February 28, 2018
A7: Source: BSE, NSE and MSEI.

Sheet 17
A1: Table 17: Trends in Cash Segment of BSE
A2: Year / Month | B2: No. of Companies Listed | C2: No. of Companies Permitted* | D2: No. of companies traded | E2: No. of Trading Days | F2: No. of Trades (Lakh) | G2: Traded Quantity (Lakh) | H2: Turnover (` crore) | I2: Average Daily Turnover (` crore) | J2: Average Trade Size (`) | K2: Demat Securities Traded (Lakh) | L2: Demat Turnover (` crore) | M2: Market Capitalisation (` crore) | N2: S&P BSE Sensex
N3: High | O3: Low | P3: Close
A4: 2017-18 | B4: 5619 | C4: 52 | D4: 2794 | E4: 246 | F4: 3585.9 | G4: 771603.31 | H4: 1082968.2 | I4: 4402.3099 | J4: 30200.737 | K4: 771603.31 | L4: 1082968.1 | M4: 14224997 | N4: 36443.98 | O4: 29241.48 | P4: 32968.68
A5: 2018-19$ | B5: 5251 | C5: 36 | D5: 2614 | E5: 229 | F5: 2889.34 | G5: 467062.61 | H5: 694613.02 | I5: 3033.2446 | J5: 24040.543 | K5: 467062.61 | L5: 694612.91 | M5: 14041530 | N5: 38989.65 | O5: 32972.56 | P5: 35867.44
A6: Apr-18 | B6: 5638 | C6: 52 | D6: 2768 | E6: 21 | F6: 233.88 | G6: 47332.62 | H6: 71629.66 | I6: 3410.9362 | J6: 30626.672 | K6: 47332.62 | L6: 71629.66 | M6: 15279535 | N6: 35213.3 | O6: 32972.56 | P6: 35160.36
A7: May-18 | B7: 5450 | C7: 52 | D7: 2755 | E7: 22 | F7: 258.01 | G7: 51335.45 | H7: 75360.5 | I7: 3425.4773 | J7: 29208.364 | K7: 51335.45 | L7: 75360.5 | M7: 14869671 | N7: 35993.53 | O7: 34302.89 | P7: 35322.38
A8: Jun-18 | B8: 5458 | C8: 36 | D8: 2698 | E8: 21 | F8: 191.19 | G8: 41057.9 | H8: 64162.59 | I8: 3055.3614 | J8: 33559.595 | K8: 41057.9 | L8: 64162.58 | M8: 14501942 | N8: 35877.41 | O8: 34784.68 | P8: 35423.48
A9: Jul-18 | B9: 5240 | C9: 36 | D9: 2763 | E9: 22 | F9: 242.84 | G9: 41849.87 | H9: 65168.48 | I9: 2962.2036 | J9: 26835.974 | K9: 41849.87 | L9: 65168.48 | M9: 15314574 | N9: 37644.59 | O9: 35106.57 | P9: 37606.58
A10: Aug-18 | B10: 5233 | C10: 36 | D10: 2823 | E10: 21 | F10: 292 | G10: 45597 | H10: 67896 | I10: 3233 | J10: 23230 | K10: 45597 | L10: 67896 | M10: 15934696 | N10: 38989.65 | O10: 37128.99 | P10: 38645.07
A11: Sep-18 | B11: 5232 | C11: 36 | D11: 2763 | E11: 18 | F11: 297.68 | G11: 38742.96 | H11: 62476.71 | I11: 3470.9283 | J11: 20987.876 | K11: 38742.96 | L11: 62476.7 | M11: 14486402 | N11: 38934.35 | O11: 35985.63 | P11: 36227.14
A12: Oct-18 | B12: 5217 | C12: 36 | D12: 2660 | E12: 21 | F12: 337.3 | G12: 43932.5 | H12: 66384.71 | I12: 3161.1767 | J12: 19681.207 | K12: 43932.5 | L12: 66384.7 | M12: 13845109 | N12: 36616.64 | O12: 33291.58 | P12: 34442.05
A13: Nov-18 | B13: 5216 | C13: 36 | D13: 2719 | E13: 20 | F13: 255.31 | G13: 38075.67 | H13: 59063.84 | I13: 2953.192 | J13: 23134.166 | K13: 38075.67 | L13: 59063.82 | M13: 14288776 | N13: 36389.22 | O13: 34303.38 | P13: 36194.3
A14: Dec-18 | B14: 5232 | C14: 36 | D14: 2756 | E14: 20 | F14: 249.04 | G14: 38058.08 | H14: 50482.91 | I14: 2524.1455 | J14: 20271.005 | K14: 38058.08 | L14: 50482.89 | M14: 14448466 | N14: 36554.99 | O14: 34426.29 | P14: 36068.33
A15: Jan-19 | B15: 5244 | C15: 36 | D15: 2663 | E15: 23 | F15: 274.63 | G15: 38852.44 | H15: 61332.33 | I15: 2666.623 | J15: 22332.713 | K15: 38852.44 | L15: 61332.31 | M15: 14099330 | N15: 36701.03 | O15: 35375.51 | P15: 36256.69
A16: Feb-19 | B16: 5251 | C16: 36 | D16: 2614 | E16: 20 | F16: 257.18 | G16: 42228.53 | H16: 50655.69 | I16: 2532.7845 | J16: 19696.59 | K16: 42228.53 | L16: 50655.67 | M16: 14041530 | N16: 37172.18 | O16: 35287.16 | P16: 35867.44
A17: $ indicates as on February 28,2019
A18: Source: BSE .

Sheet 18
A1: Table 18: Trends in Cash Segment of NSE
A2: Year / Month | B2: No. of Companies Listed | C2: No. of Companies Permitted* | D2: No. of companies traded | E2: No. of Trading Days | F2: No. of Trades (Lakh) | G2: Traded Quantity (Lakh) | H2: Turnover (` crore) | I2: Average Daily Turnover (` crore) | J2: Average Trade Size (`) | K2: Demat Securities Traded (Lakh) | L2: Demat Turnover (` crore) | M2: Market Capitalisation (` crore) | N2: Nifty 50 Index
N3: High | O3: Low | P3: Close
A4: 2017-18 | B4: 1931 | C4: 4 | D4: 1850 | E4: 246 | F4: 24913.765 | G4: 3771836.1 | H4: 7234825.7 | I4: 29409.861 | J4: 29039.471 | K4: 3771836.1 | L4: 7234825.7 | M4: 14044152 | N4: 11172 | O4: 9075 | P4: 10114
A5: 2018-19$ | B5: 1929 | C5: 4 | D5: 1917 | E5: 229 | F5: 26190.121 | G5: 3396913.9 | H5: 7251779.8 | I5: 31667.161 | J5: 27688.989 | K5: 3396913.9 | L5: 7251779.8 | M5: 13871449 | N5: 11760.2 | O5: 10004.55 | P5: 10792.5
A6: Apr-18 | B6: 1952 | C6: 4 | D6: 1817 | E6: 21 | F6: 2176.793 | G6: 298453.35 | H6: 641440.35 | I6: 30544.779 | J6: 29467.221 | K6: 298453.35 | L6: 641440.35 | M6: 15092002 | N6: 10759 | O6: 10111.3 | P6: 10739.35
A7: May-18 | B7: 1941 | C7: 4 | D7: 1820 | E7: 22 | F7: 2467.6265 | G7: 342154.59 | H7: 700012.61 | I7: 31818.755 | J7: 28367.851 | K7: 342154.59 | L7: 700012.61 | M7: 14693260 | N7: 10929.2 | O7: 10417.8 | P7: 10736.15
A8: Jun-18 | B8: 1951 | C8: 4 | D8: 1833 | E8: 21 | F8: 2225.0549 | G8: 280206.37 | H8: 591696.23 | I8: 28176.011 | J8: 26592.433 | K8: 280206.37 | L8: 591696.23 | M8: 14329072 | N8: 10893.25 | O8: 10550.9 | P8: 10714.3
A9: Jul-18 | B9: 1938 | C9: 4 | D9: 1840 | E9: 22 | F9: 2351.817 | G9: 313395.73 | H9: 662867.42 | I9: 30130.337 | J9: 28185.332 | K9: 313395.73 | L9: 662867.42 | M9: 15128449 | N9: 11366 | O9: 10604.65 | P9: 11356.5
A10: Aug-18 | B10: 1916 | C10: 4 | D10: 1841 | E10: 21 | F10: 2408.0901 | G10: 329844.7 | H10: 705869.43 | I10: 33612.83 | J10: 29312.417 | K10: 329844.7 | L10: 705869.43 | M10: 15730918 | N10: 11760.2 | O10: 11234.95 | P10: 11680.5
A11: Sep-18 | B11: 1912 | C11: 4 | D11: 1847 | E11: 18 | F11: 2405.3247 | G11: 303803.53 | H11: 688318.89 | I11: 38239.938 | J11: 28616.465 | K11: 303803.53 | L11: 688318.89 | M11: 14292302 | N11: 11751.8 | O11: 10850.3 | P11: 10930.45
A12: Oct-18 | B12: 1921 | C12: 4 | D12: 1854 | E12: 21 | F12: 2888.8986 | G12: 330715.65 | H12: 745584.25 | I12: 35504.012 | J12: 25808.599 | K12: 330715.65 | L12: 745584.25 | M12: 13693825 | N12: 11035.65 | O12: 10004.55 | P12: 10386.6
A13: Nov-18 | B13: 1922 | C13: 4 | D13: 1850 | E13: 20 | F13: 2304.4386 | G13: 282181.67 | H13: 610913.7 | I13: 30545.685 | J13: 26510.305 | K13: 282181.67 | L13: 610913.7 | M13: 14122535 | N13: 10922.45 | O13: 10341.9 | P13: 10876.75
A14: Dec-18 | B14: 1923 | C14: 4 | D14: 1856 | E14: 20 | F14: 2198.8518 | G14: 287797.21 | H14: 599917.42 | I14: 29995.871 | J14: 27283.213 | K14: 287797.21 | L14: 599917.42 | M14: 14279083 | N14: 10985.15 | O14: 10333.85 | P14: 10862.55
A15: Jan-19 | B15: 1926 | C15: 4 | D15: 1854 | E15: 23 | F15: 2386.5067 | G15: 281350.43 | H15: 665889.12 | I15: 28951.701 | J15: 27902.252 | K15: 281350.43 | L15: 665889.12 | M15: 13916643 | N15: 10987.45 | O15: 10583.65 | P15: 10830.95
A16: Feb-19 | B16: 1929 | C16: 4 | D16: 1859 | E16: 20 | F16: 2376.7194 | G16: 347010.68 | H16: 639270.41 | I16: 31963.52 | J16: 26897.177 | K16: 347010.68 | L16: 639270.41 | M16: 13871449 | N16: 11118.1 | O16: 10585.65 | P16: 10792.5
A17: Source: NSE
A18: $ indicates up to February 28,2019

Sheet 19
A1: Table 19: Trends in Cash Segment of MSEI
A2: Year/Month | B2: No. of Companies Listed | C2: No. of Companies Permitted # | D2: No. of Companies Traded | E2: No. of Trading Days | F2: No. of Trades (Lakh) | G2: Traded Quantity (Lakh) | H2: Turnover (₹ crore) | I2: Average Daily Turnover (₹ crore) | J2: Average Trade Size (`) | K2: Demat Securities Traded (Lakh) | L2: Demat Turnover (₹ crore) | M2: Market Capitalisation (₹ crore) | N2: SX 50 Index
N3: High | O3: Low | P3: Close
A4: 2017-18 | B4: 270 | C4: 1326 | D4: 12 | E4: 246 | F4: 0.02823 | G4: 151.78948 | H4: 192.76941 | I4: 0.78361548 | J4: 682853.02 | K4: 0 | L4: 0 | M4: 13896724 | N4: 21581.92 | O4: 17684.5 | P4: 19686.18
A5: 2018-19$ | B5: 287 | C5: 1311 | D5: 8 | E5: 229 | F5: 0.01563 | G5: 11.42328 | H5: 24.514193 | I5: 0.10704888 | J5: 156840.64 | K5: 11.42317 | L5: 24.508544 | M5: 13687100 | N5: 22872.75 | O5: 19644.59 | P5: 21135.33
A6: Apr-18 | B6: 273 | C6: 1329 | D6: 5 | E6: 21 | F6: 0.00163 | G6: 0.39826 | H6: 1.2880075 | I6: 0.061333691 | J6: 79019 | K6: 0 | L6: 0 | M6: 14855347 | N6: 21070.86 | O6: 19735.82 | P6: 21070.86
A7: May-18 | B7: 277 | C7: 1330 | D7: 4 | E7: 22 | F7: 0.00199 | G7: 0.9141 | H7: 1.8949297 | I7: 0.08613317 | J7: 95222.601 | K7: 0 | L7: 0 | M7: 14469622 | N7: 21084.31 | O7: 20354.57 | P7: 20866.91
A8: Jun-18 | B8: 277 | C8: 1330 | D8: 3 | E8: 21 | F8: 0.00024 | G8: 0.1237 | H8: 0.393194 | I8: 0.018723524 | J8: 163830.83 | K8: 0 | L8: 0 | M8: 14088829 | N8: 21212.67 | O8: 20608.49 | P8: 20874.72
A9: Jul-18 | B9: 277 | C9: 1329 | D9: 3 | E9: 22 | F9: 0.00028 | G9: 0.15975 | H9: 0.4017769 | I9: 0.018262586 | J9: 143491.75 | K9: 0.1598 | L9: 0.4018 | M9: 14873846 | N9: 22078.12 | O9: 20756.42 | P9: 22078.12
A10: Aug-18 | B10: 278 | C10: 1329 | D10: 2 | E10: 21 | F10: 0 | G10: 0.31 | H10: 0.92 | I10: 0.04 | J10: 107218.3 | K10: 0.31 | L10: 0.92 | M10: 15483703 | N10: 22872.75 | O10: 21884.71 | P10: 22759.78
A11: Sep-18 | B11: 282 | C11: 1317 | D11: 2 | E11: 18 | F11: 0.0009 | G11: 0.5395 | H11: 1.1962385 | I11: 0.066457694 | J11: 132915.39 | K11: 0.5395 | L11: 1.1962 | M11: 14072761 | N11: 22605.73 | O11: 21418.2 | P11: 21418.2
A12: Oct-18 | B12: 281 | C12: 1320 | D12: 2 | E12: 21 | F12: 0.00082 | G12: 0.3928 | H12: 0.9920585 | I12: 0.047240881 | J12: 120982.74 | K12: 0.3928 | L12: 0.9920585 | M12: 13489960 | N12: 21585.1 | O12: 19644.59 | P12: 20329.99
A13: Nov-18 | B13: 282 | C13: 1319 | D13: 3 | E13: 20 | F13: 0.00127 | G13: 0.87926 | H13: 1.7222751 | I13: 0.086113755 | J13: 135612.21 | K13: 0.87926 | L13: 1.72 | M13: 13917651 | N13: 21349.05 | O13: 20309.95 | P13: 21349.05
A14: Dec-18 | B14: 282 | C14: 1318 | D14: 2 | E14: 20 | F14: 0.00124 | G14: 0.446 | H14: 1.2421985 | I14: 0.062109925 | J14: 100177.3 | K14: 0.446 | L14: 1.2422 | M14: 14070348 | N14: 21498.26 | O14: 20597.85 | P14: 21273.63
A15: Jan-19 | B15: 284 | C15: 1318 | D15: 6 | E15: 23 | F15: 0.00377 | G15: 4.67015 | H15: 9.2433544 | I15: 0.40188498 | J15: 245181.82 | K15: 4.67015 | L15: 9.2433544 | M15: 13741805 | N15: 21515.91 | O15: 20909.05 | P15: 21284.45
A16: Feb-19 | B16: 287 | C16: 1311 | D16: 4 | E16: 20 | F16: 0.00263 | G16: 2.58796 | H16: 5.2180822 | I16: 0.26090411 | J16: 198406.17 | K16: 2.588 | L16: 5.2181 | M16: 13687100 | N16: 21745.26 | O16: 20799.89 | P16: 21135.33
A17: $ indicates up to February 28,2019
A18: Source: MSEI

Sheet 20
A1: Table 20: City-wise Distribution of Turnover on Cash Segments of BSE and NSE
A2: (Percentage share in Turnover)
A3: S.No | B3: City | C3: BSE | E3: NSE | G3: MSEI
C4: 2017-18 | D4: Feb-19 | E4: 2017-18 | F4: Feb-19 | G4: 2017-18 | H4: Feb-19
A5: 1 | B5: Ahmedabad | C5: 2.9307028 | D5: 2.2956619 | E5: 3.06 | F5: 1.95 | G5: 0 | H5: 0
A6: 2 | B6: Bengaluru | C6: 0.33716712 | D6: 0.84120027 | E6: 4.42 | F6: 3.84 | G6: 0 | H6: 0
A7: 3 | B7: Vadodra | C7: 0.88230549 | D7: 0.95442193 | E7: 0.38 | F7: 0.21 | G7: 0 | H7: 0
A8: 4 | B8: Bhubneshwar | C8: 0.018744452 | D8: 0.019565045 | E8: 0 | F8: 0 | G8: 0 | H8: 0
A9: 5 | B9: Chennai | C9: 1.0669646 | D9: 1.1867363 | E9: 0.9 | F9: 0.73 | G9: 0 | H9: 0
A10: 6 | B10: Ernakulum | C10: 0.11806655 | D10: 0.1041521 | E10: 0.86 | F10: 0.78 | G10: 0 | H10: 0
A11: 7 | B11: Coimbatore | C11: 0.052256386 | D11: 0.048235268 | E11: 0.07 | F11: 0.04 | G11: 0 | H11: 0
A12: 8 | B12: New Delhi | C12: 3.0446179 | D12: 1.4159115 | E12: 6.79 | F12: 7.18 | G12: 4.28 | H12: 39.39
A13: 9 | B13: Guwahati | C13: 0.063264665 | D13: 0.037615883 | E13: 0 | F13: 0 | G13: 0 | H13: 0
A14: 10 | B14: Hyderabad | C14: 0.34063164 | D14: 0.8608159 | E14: 3.51 | F14: 3.17 | G14: 0.07 | H14: 0
A15: 11 | B15: Indore | C15: 0.39403013 | D15: 0.23431157 | E15: 0.53 | F15: 0.36 | G15: 0.24 | H15: 0
A16: 12 | B16: Jaipur | C16: 0.64179047 | D16: 0.52402184 | E16: 0.48 | F16: 0.27 | G16: 0.35 | H16: 0
... A25: 21 | B25: Others | C25: 25.589131 | D25: 34.911506 | E25: 10.26 | F25: 11.33 | G25: 53.24 | H25: 14.97
B26: Total | C26: 100 | D26: 100 | E26: 99.98 | F26: 100 | G26: 100.01 | H26: 100.01
A28: 1. The city-wise distribution of turnover is based on the cities uploaded in the UCC database of the Exchange for clientele trades and members registered office city for proprietary trades.
A29: Source: BSE, NSE and MSEI.

Sheet 21
A1: Table 21: Category-wise Share of Turnover in Cash Segment of BSE
A2: Year / Month | B2: Percentage Share in Turnover
B3: Proprietary | C3: FPIs | D3: Mutual Funds | E3: Banks | F3: Others
A4: 2017-18 | B4: 16.664204 | C4: 15.729893 | D4: 8.2295987 | E4: 0.14340144 | F4: 59.232903
A5: 2018-19$ | B5: 22.860909 | C5: 12.405455 | D5: 8.1818182 | E5: 0.052727273 | F5: 56.498182
A6: Apr-18 | B6: 19.98 | C6: 15.4 | D6: 8.03 | E6: 0.05 | F6: 56.54
A7: May-18 | B7: 21.77 | C7: 15.09 | D7: 9.47 | E7: 0.05 | F7: 53.62
A8: Jun-18 | B8: 18.97 | C8: 18.77 | D8: 8.2 | E8: 0.12 | F8: 53.94
A9: Jul-18 | B9: 20.54 | C9: 15.82 | D9: 7.9 | E9: 0.04 | F9: 55.7
A10: Aug-18 | B10: 22.8 | C10: 10.49 | D10: 7.1 | E10: 0.06 | F10: 59.55
A11: Sep-18 | B11: 24.6 | C11: 12.03 | D11: 7.67 | E11: 0.04 | F11: 55.67
A12: Oct-18 | B12: 26.14 | C12: 9.53 | D12: 8.43 | E12: 0.05 | F12: 55.85
A13: Nov-18 | B13: 22.08 | C13: 13.98 | D13: 9.73 | E13: 0.03 | F13: 54.18
A14: Dec-18 | B14: 26.71 | C14: 8.96 | D14: 5.83 | E14: 0.04 | F14: 58.46
A15: Jan-19 | B15: 23.06 | C15: 8.89 | D15: 11.98 | E15: 0.05 | F15: 56.02
A16: Feb-19 | B16: 24.78 | C16: 7.89 | D16: 5.66 | E16: 0.05 | F16: 61.62
A17: $ indicates as on February 28,2019
A18: Source: BSE.

Sheet 22
A1: Table 22: Category-wise Share of Turnover in Cash Segment of NSE
A2: Year /Month | B2: Percentage Share in Turnover
B3: Proprietary | C3: FPIs | D3: Mutual Funds | E3: Banks | F3: Others
A4: 2017-18 | B4: 17.99 | C4: 16.09 | D4: 7.29 | E4: 0.49 | F4: 58.14
A5: 2018-19$ | B5: 21.59 | C5: 15 | D5: 7.49 | E5: 0.23 | F5: 55.69
A6: Apr-18 | B6: 19.26 | C6: 14.05 | D6: 7.29 | E6: 0.37 | F6: 59.02
A7: May-18 | B7: 20.1 | C7: 16.42 | D7: 7.54 | E7: 0.3 | F7: 55.64
A8: Jun-18 | B8: 20.02 | C8: 17.25 | D8: 8.03 | E8: 0.25 | F8: 54.45
A9: Jul-18 | B9: 22.16 | C9: 13.91 | D9: 7.87 | E9: 0.27 | F9: 55.79
A10: Aug-18 | B10: 21.82 | C10: 13.3 | D10: 7.25 | E10: 0.28 | F10: 57.35
A11: Sep-18 | B11: 22.72 | C11: 16.15 | D11: 7.44 | E11: 0.24 | F11: 53.45
A12: Oct-18 | B12: 22.71 | C12: 15.83 | D12: 8.12 | E12: 0.12 | F12: 53.22
A13: Nov-18 | B13: 21.26 | C13: 15.34 | D13: 7.38 | E13: 0.17 | F13: 55.85
A14: Dec-18 | B14: 22.84 | C14: 13.06 | D14: 7.32 | E14: 0.18 | F14: 56.6
A15: Jan-19 | B15: 22.03 | C15: 14.31 | D15: 6.84 | E15: 0.17 | F15: 56.65
A16: Feb-19 | B16: 22.61 | C16: 15.43 | D16: 7.32 | E16: 0.18 | F16: 54.46
A17: Source: NSE.
A18: $ indicates up to February 28,2019

Sheet 23
A1: Table 23: Category-wise Share of Turnover in Cash Segment of MSEI
A2: Year / Month | B2: Percentage Share in Turnover
B3: Proprietary | C3: FPIs | D3: Mutual Funds | E3: Banks | F3: Others
A4: 2017-18 | B4: 0 | C4: 0 | D4: 0 | E4: 0 | F4: 100
A5: 2018-19$ | B5: 0 | C5: 0 | D5: 0 | E5: 0 | F5: 100
A6: Apr-18 | B6: 0 | C6: 0 | D6: 0 | E6: 0 | F6: 100
A7: May-18 | B7: 0 | C7: 0 | D7: 0 | E7: 0 | F7: 100
A8: Jun-18 | B8: 0 | C8: 0 | D8: 0 | E8: 0 | F8: 100
A9: Jul-18 | B9: 0 | C9: 0 | D9: 0 | E9: 0 | F9: 100
A10: Aug-18 | B10: 0 | C10: 0 | D10: 0 | E10: 0 | F10: 100
A11: Sep-18 | B11: 0 | C11: 0 | D11: 0 | E11: 0 | F11: 100
A12: Oct-18 | B12: 0 | C12: 0 | D12: 0 | E12: 0 | F12: 100
A13: Nov-18 | B13: 0 | C13: 0 | D13: 0 | E13: 0 | F13: 100
A14: Dec-18 | B14: 0 | C14: 0 | D14: 0 | E14: 0 | F14: 100
A15: Jan-19 | B15: 0 | C15: 0 | D15: 0 | E15: 0 | F15: 100
A16: Feb-19 | B16: 0 | C16: 0 | D16: 0 | E16: 0 | F16: 100
A17: $ indicates up to February 28,2019
A18: Source: MSEI.

Sheet 24
A1: Table 24: Component Stocks: S&P BSE Sensex during Feb-19
A2: Sl.No | B2: Name of Security | C2: Issued Capital (` crore) | D2: Free Float Market Capitalisation (` crore) | E2: Weightage (Percent) | F2: Beta | G2: R 2 | H2: Daily Volatility (Percent) | I2: Monthly Return (Percent) | J2: Impact Cost (Percent)
A3: 1 | B3: HDFC BANK | C3: 544.39 | D3: 446947.87 | E3: 12.28 | F3: 0.71 | G3: 0.32 | H3: 0.99 | I3: 0.05 | J3: 0.03
A4: 2 | B4: RELIANCE | C4: 6338.67 | D4: 397773.8 | E4: 10.92 | F4: 1.46 | G4: 0.45 | H4: 1.7 | I4: 0.36 | J4: 0.02
A5: 3 | B5: HDFC | C5: 344.06 | D5: 316366.79 | E5: 8.69 | F5: 1.23 | G5: 0.46 | H5: 1.42 | I5: -4.26 | J5: 0.04
A6: 4 | B6: INFOSYS LTD | C6: 2184.33 | D6: 278927.17 | E6: 7.66 | F6: 0.87 | G6: 0.02 | H6: 4.5 | I6: -2.09 | J6: 0.03
A7: 5 | B7: ITC LTD. | C7: 1225.08 | D7: 235368.54 | E7: 6.46 | F7: 0.93 | G7: 0.33 | H7: 1.28 | I7: -0.93 | J7: 0.04
A8: 6 | B8: ICICI BANK | C8: 1288.66 | D8: 223739.68 | E8: 6.14 | F8: 1.28 | G8: 0.27 | H8: 1.94 | I8: -4.24 | J8: 0.03
A9: 7 | B9: TCS LTD. | C9: 375.24 | D9: 208478.76 | E9: 5.73 | F9: -0.03 | G9: 0 | H9: 4.73 | I9: -1.51 | J9: 0.03
A10: 8 | B10: LARSEN & TOU | C10: 280.52 | D10: 157731.59 | E10: 4.33 | F10: 1 | G10: 0.34 | H10: 1.34 | I10: -1.44 | J10: 0.04
A11: 9 | B11: KOTAK MAH.BK | C11: 954.02 | D11: 143094.9 | E11: 3.93 | F11: 0.99 | G11: 0.25 | H11: 1.57 | I11: -3.26 | J11: 0.04
A12: 10 | B12: AXIS BANK | C12: 514.18 | D12: 125489.49 | E12: 3.45 | F12: 1.21 | G12: 0.26 | H12: 1.85 | I12: -1.88 | J12: 0.03
A13: 11 | B13: HIND UNI LT | C13: 216.46 | D13: 123665.73 | E13: 3.4 | F13: 0.77 | G13: 0.21 | H13: 1.33 | I13: -1.75 | J13: 0.04
A14: 12 | B14: STATE BANK | C14: 892.46 | D14: 101111.12 | E14: 2.78 | F14: 1.36 | G14: 0.32 | H14: 1.89 | I14: -8.04 | J14: 0.03
... A33: 31 | B33: TATAMTRTDVR | C33: 101.7 | D33: 4451.94 | E33: 0.12 | F33: 1.4 | G33: 0.22 | H33: 2.37 | I33: -6.61 | J33: 0.15
A34: 1. Beta & R2 are calculated for the trailing 12 months. Beta measures the degree to which any portfolio of stocks is affected as compared to the effect on the market as a whole.
A35: 2. The coefficient of determination (R2) measures the strength of relationship between two variables the return on a security versus that of the market.
A36: 3. Volatility is the standard deviation of the daily returns for the trailing 12 months.
A37: 4. Impact cost is calculated as the difference between actual buy price and ideal buy price, divided by ideal buy price, multiplied by 100. Hence ideal price is calculated as (best buy + best sell)/2.
A38: 5. The above is calculated for a month for the portfolio size of ` 5 lakh. It is calculated for the current month.
A39: Source: BSE.

Sheet 25
A1: Table 25: Component Stocks: Nifty 50 Index during Feb-19
A2: Sl. No | B2: Name of Security | C2: Issued Capital (`Crore) | D2: Free Float Market Capitalisation (` crore) | E2: Weightage (Percent) | F2: Beta | G2: R 2 | H2: Daily Volatility (Percent) | I2: Monthly Return (Percent) | J2: Impact Cost (Percent)
A3: 1 | B3: HDFC Bank Ltd. | C3: 543.7 | D3: 446176.6 | E3: 10.33 | F3: 0.68 | G3: 0.29 | H3: 0.79 | I3: -0.12 | J3: 0.02
A4: 2 | B4: Reliance Industries Ltd. | C4: 6338.56 | D4: 421366.6 | E4: 9.76 | F4: 1.41 | G4: 0.43 | H4: 1.41 | I4: 0.32 | J4: 0.02
A5: 3 | B5: Housing Development Finance Corporation Ltd. | C5: 343.31 | D5: 303408.82 | E5: 7.03 | F5: 1.21 | G5: 0.44 | H5: 1.15 | I5: -4.22 | J5: 0.02
A6: 4 | B6: Infosys Ltd. | C6: 2184.3 | D6: 279084.41 | E6: 6.46 | F6: 0.65 | G6: 0.12 | H6: 1.26 | I6: -2.03 | J6: 0.02
A7: 5 | B7: I T C Ltd. | C7: 1224.51 | D7: 236617.41 | E7: 5.48 | F7: 0.91 | G7: 0.31 | H7: 0.89 | I7: -0.93 | J7: 0.03
A8: 6 | B8: ICICI Bank Ltd. | C8: 1288.02 | D8: 225500.21 | E8: 5.22 | F8: 1.26 | G8: 0.27 | H8: 1.3 | I8: -3.92 | J8: 0.03
A9: 7 | B9: Tata Consultancy Services Ltd. | C9: 375.24 | D9: 208394.69 | E9: 4.83 | F9: 0.45 | G9: 0.05 | H9: 1.71 | I9: -1.52 | J9: 0.02
A10: 8 | B10: Kotak Mahindra Bank Ltd. | C10: 953.59 | D10: 161952.49 | E10: 3.75 | F10: 0.96 | G10: 0.24 | H10: 1.08 | I10: -3.4 | J10: 0.02
A11: 9 | B11: Larsen & Toubro Ltd. | C11: 280.44 | D11: 159544.06 | E11: 3.69 | F11: 1.01 | G11: 0.35 | H11: 1.2 | I11: -1.62 | J11: 0.03
A12: 10 | B12: Axis Bank Ltd. | C12: 513.98 | D12: 125818.44 | E12: 2.91 | F12: 1.21 | G12: 0.26 | H12: 0.9 | I12: -1.82 | J12: 0.02
A13: 11 | B13: Hindustan Unilever Ltd. | C13: 216.46 | D13: 123769.11 | E13: 2.87 | F13: 0.77 | G13: 0.21 | H13: 0.93 | I13: -1.74 | J13: 0.02
A14: 12 | B14: State Bank of India | C14: 892.46 | D14: 100848.73 | E14: 2.34 | F14: 1.37 | G14: 0.33 | H14: 1.33 | I14: -8.38 | J14: 0.02
... A52: 50 | B52: Hindustan Petroleum Corporation Ltd. | C52: 1523.82 | D52: 16676.94 | E52: 0.39 | F52: 1.43 | G52: 0.13 | H52: 2.1 | I52: -4.35 | J52: 0.03
A53: 1. Beta & R2 are calculated for the the trailing 12 months. Beta measures the degree to which any portfolio of stocks is affected as compared to the effect on the market as a whole.
A54: 2. The coefficient of determination (R2) measures the strength of relationship between two variables the return on a security versus that of the market.
A55: 3. Volatility is the standard deviation of the daily returns for the the trailing 12 months.
A56: 4. Impact cost is calculated as the difference between actual buy price and ideal buy price, divided by ideal buy price, multiplied by 100. Hence ideal price is calculated as (best buy + best sell)/2.
A57: 5. Impact Cost for Nifty 50 is for a portfolio of Rs. 50 Lakhs and is weightage average impact cost.
A58: Source: NSE.

Sheet 26
A1: Table 26: Component Stocks: SX40 Index
A2: S.No. | B2: Name of Security | C2: Issued Capital (₹ crore) | D2: Free Float Market Capitalisation (₹ crore) | E2: Weightage (Percent) | F2: Beta | G2: R2 | H2: Daily Volatility (Percent) | I2: Monthly Return (Percent) | J2: Impact Cost (Percent) *
A3: 1 | B3: HDFCBANK | C3: 544.38955 | D3: 444011.59 | E3: 11.08 | F3: 0.67 | G3: 0.27 | H3: 0.88 | I3: -0.12 | J3: Na
A4: 2 | B4: RELIANCE | C4: 6338.666 | D4: 398928.7 | E4: 9.96 | F4: 1.45 | G4: 0.44 | H4: 1.67 | I4: 0.32 | J4: Na
A5: 3 | B5: HDFC | C5: 344.04356 | D5: 304728.99 | E5: 7.61 | F5: 1.2 | G5: 0.41 | H5: 1.3 | I5: -4.41 | J5: Na
A6: 4 | B6: INFY | C6: 2184.3262 | D6: 278134.91 | E6: 6.94 | F6: 0.76 | G6: 0.15 | H6: 1.37 | I6: -2.08 | J6: Na
A7: 5 | B7: ITC | C7: 1224.6386 | D7: 238033.45 | E7: 5.94 | F7: 0.95 | G7: 0.32 | H7: 1.2 | I7: -0.94 | J7: Na
A8: 6 | B8: ICICIBANK | C8: 1288.528 | D8: 225519.99 | E8: 5.63 | F8: 1.22 | G8: 0.24 | H8: 1.65 | I8: -4.08 | J8: Na
A9: 7 | B9: TCS | C9: 382.85752 | D9: 223144.71 | E9: 5.57 | F9: 0.56 | G9: 0.08 | H9: 1.34 | I9: -1.55 | J9: Na
A10: 8 | B10: LT | C10: 280.4705 | D10: 159009.55 | E10: 3.97 | F10: 1.03 | G10: 0.35 | H10: 1.24 | I10: -1.65 | J10: Na
A11: 9 | B11: KOTAKBANK | C11: 954.017 | D11: 150906.39 | E11: 3.77 | F11: 0.96 | G11: 0.23 | H11: 1.36 | I11: -3.52 | J11: Na
A12: 10 | B12: AXISBANK | C12: 514.08437 | D12: 140069.17 | E12: 3.5 | F12: 1.19 | G12: 0.24 | H12: 1.62 | I12: -1.85 | J12: Na
A13: 11 | B13: HINDUNILVR | C13: 216.46489 | D13: 123059.06 | E13: 3.07 | F13: 0.79 | G13: 0.21 | H13: 0.99 | I13: -1.77 | J13: Na
A14: 12 | B14: SBIN | C14: 892.46115 | D14: 101453.64 | E14: 2.53 | F14: 1.32 | G14: 0.29 | H14: 1.45 | I14: -9.14 | J14: Na
... A42: 40 | B42: ADANIPORTS | C42: 414.19035 | D42: 25439.827 | E42: 0.63 | F42: 1.4 | G42: 0.24 | H42: 3.2 | I42: -3.93 | J42: Na
A44: 1. Market Cap, Beta & R2 as on the last day of the month
A45: 2. Beta & R2 are calculated for the trailing 12 months
A46: 3. Volatility for the current month
A47: 4. *Since there is no trading in the SX40 constituents, the Impact Cost for the given stocks is NIL.
A48: Source: MSEI.

Sheet 27
A1: Table 27: Advances/Declines in Cash Segment of BSE, NSE and MSEI
A2: Year/ Month | B2: BSE | E2: NSE | H2: MSEI
B3: Advances | C3: Declines | D3: Advance/Decline Ratio | E3: Advances | F3: Declines | G3: Advance/Decline Ratio | H3: Advances | I3: Declines | J3: Advance/Decline Ratio
A4: 2017-18 | B4: 703 | C4: 2691 | D4: 0.26124117 | E4: 1202 | F4: 512 | G4: 2.348 | H4: 1 | I4: 8 | J4: 0.13
A5: 2018-19$ | B5: 1173 | C5: 2706 | D5: 0.43348115 | E5: 595 | F5: 1264 | G5: 0.47 | H5: 2 | I5: 4 | J5: 0.5
A6: Apr-18 | B6: 1982 | C6: 1449 | D6: 1.3678399 | E6: 1180 | F6: 659 | G6: 1.79 | H6: 2 | I6: 3 | J6: 0.67
A7: May-18 | B7: 992 | C7: 2448 | D7: 0.40522876 | E7: 486 | F7: 1378 | G7: 0.35 | H7: 0 | I7: 4 | J7: 0
A8: Jun-18 | B8: 779 | C8: 2651 | D8: 0.29 | E8: 361 | F8: 1517 | G8: 0.24 | H8: 0 | I8: 2 | J8: 0
A9: Jul-18 | B9: 842 | C9: 2579 | D9: 0.32648313 | E9: 415 | F9: 1478 | G9: 0.28 | H9: 1 | I9: 2 | J9: 0.5
A10: Aug-18 | B10: 2080 | C10: 1415 | D10: 1.4699647 | E10: 1254 | F10: 637 | G10: 1.97 | H10: 0 | I10: 2 | J10: 0
A11: Sep-18 | B11: 1174 | C11: 2331 | D11: 0.5036465 | E11: 532 | F11: 1361 | G11: 0.39 | H11: 1 | I11: 1 | J11: 1
A12: Oct-18 | B12: 481 | C12: 2973 | D12: 0.16178944 | E12: 159 | F12: 1741 | G12: 0.09 | H12: 1 | I12: 0 | J12: 0
A13: Nov-18 | B13: 1984 | C13: 1457 | D13: 1.3617021 | E13: 1210 | F13: 697 | G13: 1.74 | H13: 1 | I13: 1 | J13: 1
A14: Dec-18 | B14: 1314 | C14: 2095 | D14: 0.62720764 | E14: 741 | F14: 1169 | G14: 0.63 | H14: 1 | I14: 0 | J14: 0
A15: Jan-19 | B15: 1672 | C15: 1219 | D15: 1.3716161 | E15: 789 | F15: 1120 | G15: 0.7 | H15: 1 | I15: 2 | J15: 0.5
A16: Feb-19 | B16: 558 | C16: 2335 | D16: 0.23897216 | E16: 325 | F16: 1588 | G16: 0.2 | H16: 1 | I16: 3 | J16: 0.33
A17: $ indicates as on February 28, 2018
A18: Advance/Decline is calculated based on the average price methodology.
A19: Source: BSE, NSE and MSEI.

Sheet 28
A1: Table 28: Trading Frequency in Cash Segment of BSE, NSE and MSEI
A2: Month | B2: BSE | E2: NSE | H2: MSEI
B3: No. of Companies Listed | C3: No. of Companies Traded | D3: Percent of Traded to Listed | E3: No. of Companies Listed | F3: No. of Companies Traded | G3: Percent of Traded to Listed | H3: No. of Companies Listed | I3: No. of Companies Traded | J3: Percent of Traded to Listed
A4: 2017-18 | B4: 5619 | C4: 2794 | D4: 49.72415 | E4: 1931 | F4: 1850 | G4: 95.805282 | H4: 270 | I4: 12 | J4: 4.4444444
A5: 2018-19$ | B5: 5251 | C5: 2614 | D5: 49.780994 | E5: 1929 | F5: 1917 | G5: 99.377916 | H5: 287 | I5: 8 | J5: 2.7874564
A6: Apr-18 | B6: 5638 | C6: 2768 | D6: 49.095424 | E6: 1952 | F6: 1817 | G6: 93.084016 | H6: 273 | I6: 5 | J6: 1.8315018
A7: May-18 | B7: 5450 | C7: 2755 | D7: 50.550459 | E7: 1941 | F7: 1820 | G7: 93.7661 | H7: 277 | I7: 4 | J7: 1.4440433
A8: Jun-18 | B8: 5458 | C8: 2698 | D8: 49.432026 | E8: 1951 | F8: 1833 | G8: 93.95182 | H8: 277 | I8: 3 | J8: 1.0830325
A9: Jul-18 | B9: 5240 | C9: 2763 | D9: 52.729008 | E9: 1938 | F9: 1840 | G9: 94.94324 | H9: 277 | I9: 3 | J9: 1.0830325
A10: Aug-18 | B10: 5233 | C10: 2823 | D10: 53.946111 | E10: 1916 | F10: 1841 | G10: 96.085595 | H10: 278 | I10: 2 | J10: 0.71942446
A11: Sep-18 | B11: 5232 | C11: 2763 | D11: 52.809633 | E11: 1912 | F11: 1847 | G11: 96.600418 | H11: 282 | I11: 2 | J11: 0.70921986
A12: Oct-18 | B12: 5217 | C12: 2660 | D12: 50.987157 | E12: 1921 | F12: 1854 | G12: 96.512233 | H12: 281 | I12: 2 | J12: 0.71174377
A13: Nov-18 | B13: 5216 | C13: 2719 | D13: 52.128067 | E13: 1922 | F13: 1850 | G13: 96.253902 | H13: 282 | I13: 3 | J13: 1.0638298
A14: Dec-18 | B14: 5232 | C14: 2756 | D14: 52.675841 | E14: 1923 | F14: 1856 | G14: 96.515861 | H14: 282 | I14: 2 | J14: 0.70921986
A15: Jan-19 | B15: 5244 | C15: 2663 | D15: 50.781846 | E15: 1926 | F15: 1854 | G15: 96.261682 | H15: 284 | I15: 6 | J15: 2.1126761
A16: Feb-19 | B16: 5251 | C16: 2614 | D16: 49.780994 | E16: 1929 | F16: 1859 | G16: 96.371177 | H16: 287 | I16: 4 | J16: 1.3937282
A17: $ indicates as on February 28,2019
A18: Source: BSE, NSE and MSEI.

Sheet 29
A1: Table 29: Daily Volatility of Major Indices (percent)
A2: Year / Month | B2: BSE Sensex | C2: BSE 100 | D2: BSE 500 | E2: Nifty 50 | F2: Nifty Next 50 | G2: Nifty 500 | H2: SX40
